Workbook
Name a_c2_c0: Sheep!$K$245:$M$245
Name arable: General!$J$69:$J$77
Name ave_pad_distance: Mach!$B$5
Name bank_bal_start: Finance!$B$4
Name bas: Labour!$N$72:$P$76
Name BaseLevelInput: Annual!$K$464:$K$473
Name BaseLevelInput: Understory!$K$449:$K$458
Name capital_limit: Finance!$B$2
Name chem: Crop!$G$349:$AU$404
Name chem_by_lmu: Crop!$H$678:$Q$679
Name chem_cost: Crop!$G$286:$AA$341
Name chem_info: Crop!$I$694:$L$698
Name CPDry: Annual!$V$655:$V$664
Name CPDry: Understory!$V$640:$V$649
Name CPGrn: Annual!$X$519:$X$528
Name CPGrn: Understory!$X$504:$X$513
Name daily_harvest_hours: Mach!$B$8
Name daily_hours: Labour!$G$51:$J$55
Name daily_seed_hours: Mach!$B$10
Name Date_Destocking: Annual!$J$149:$S$149
Name Date_Destocking: Understory!$J$145:$S$145
Name Date_ResownGrazing: Annual!$J$155:$S$155
Name Date_ResownGrazing: Understory!$J$151:$S$151
Name Date_Seeding: Annual!$J$151:$S$151
Name Date_Seeding: Understory!$J$147:$S$147
Name DigDryAve: Annual!$J$655:$J$754
Name DigDryAve: Understory!$J$640:$J$739
Name DigDryRange: Annual!$K$655:$K$754
Name DigDryRange: Understory!$K$640:$K$739
Name DigGrn: Annual!$J$519:$R$618
Name DigGrn: Understory!$J$504:$R$603
Name DigPOC: Annual!$I$894:$R$903
Name DigPOC: Understory!$I$879:$R$888
Name DigRednSenesce: Annual!$T$519:$T$618
Name DigRednSenesce: Understory!$T$504:$T$603
Name DigSpread: Annual!$V$519:$V$618
Name DigSpread: Understory!$V$504:$V$603
Name dry_seed_start: Crop!$I$38
Name empty_rate: 'Sup Feed'!$H$77:$J$85
Name end_contract_seeding_gs1_z: Periods!$G$59:$P$59
Name end_wet_seeding_gs1_z: Periods!$G$52:$P$52
Name EndGS: Annual!$J$79:$S$79
Name EndGS: Understory!$J$75:$S$75
Name ErosionLimit: Annual!$K$920:$S$1019
Name ErosionLimit: Understory!$K$905:$S$1004
Name FaG_LMU: Annual!$M$164:$U$164
Name FaG_LMU: Understory!$M$160:$U$160
Name FaG_PropnGrn: Annual!$L$166
Name FaG_PropnGrn: Understory!$L$162
Name feed_freq: 'Sup Feed'!$O$75
Name feed_periods: Sheep!$J$67:$L$168
Name feed_rate: 'Sup Feed'!$N$78:$P$85
Name fert: Crop!$G$413:$AU$468
Name fert_by_lmu: Crop!$H$657:$Q$662
Name fert_info: Crop!$H$601:$K$606
Name fert_passes: Crop!$G$474:$AU$529
Name fert_prep: Labour!$N$100:$P$103
Name fixed_crop_monitoring: Labour!$E$127:$Q$128
Name fixed_rotphases: Crop!$H$162:$M$216
Name FOOatGrazing: Annual!$L$164

Sheet Home

Sheet General
C3: «
E4: Däta | G4: Property ID | I4: note
H6: ID | I6: EWW
C7: 0
G9: =G4 -> Property ID | W9: »
C13: «
G14: Landuses | I14: *These shoud match the landuse arrays in structural.py
P15: phase_can_change_kp7 | U15: phase_can_reduce_kp7
G16: Crop Landuses | H16: Exists | I16: Included | K16: Pasture landuses | L16: Exists | M16: Included | O16: All landuses | P16: =P107 -> Dry seeding | Q16: =Q107 -> Brk | R16: =R107 -> Quality brk | S16: =S107 -> Spring | U16: =P16 -> Dry seeding | V16: =Q16 -> Brk | W16: =R16 -> Quality brk | X16: =S16 -> Spring
G17: b | H17: TRUE | I17: TRUE | K17: a | L17: TRUE | M17: TRUE | O17: a | P17: TRUE | Q17: TRUE | R17: TRUE | S17: FALSE | U17: TRUE | V17: TRUE | W17: FALSE | X17: FALSE
G18: bd | H18: TRUE | I18: TRUE | K18: a2 | L18: TRUE | M18: TRUE | O18: a2 | P18: TRUE | Q18: TRUE | R18: TRUE | S18: FALSE | U18: TRUE | V18: TRUE | W18: TRUE | X18: FALSE
G19: f | H19: FALSE | I19: FALSE | K19: m | L19: TRUE | M19: TRUE | O19: b | P19: TRUE | Q19: TRUE | R19: TRUE | S19: FALSE | U19: TRUE | V19: TRUE | W19: FALSE | X19: FALSE
G20: h | H20: FALSE | I20: FALSE | K20: j | L20: FALSE | M20: FALSE | O20: bd | P20: TRUE | Q20: TRUE | R20: TRUE | S20: FALSE | U20: TRUE | V20: TRUE | W20: FALSE | X20: FALSE
G21: i | H21: FALSE | I21: FALSE | K21: jc | L21: FALSE | M21: FALSE | O21: f | P21: TRUE | Q21: TRUE | R21: TRUE | S21: FALSE | U21: TRUE | V21: TRUE | W21: FALSE | X21: FALSE
G22: k | H22: FALSE | I22: FALSE | K22: s | L22: TRUE | M22: TRUE | O22: h | P22: TRUE | Q22: TRUE | R22: TRUE | S22: FALSE | U22: TRUE | V22: TRUE | W22: FALSE | X22: FALSE
G23: l | H23: TRUE | I23: TRUE | K23: sp | L23: TRUE | M23: FALSE | O23: i | P23: TRUE | Q23: TRUE | R23: TRUE | S23: FALSE | U23: TRUE | V23: TRUE | W23: FALSE | X23: FALSE
G24: lf | H24: TRUE | I24: TRUE | K24: t | L24: FALSE | M24: FALSE | O24: j | P24: TRUE | Q24: TRUE | R24: TRUE | S24: FALSE | U24: TRUE | V24: TRUE | W24: FALSE | X24: FALSE
G25: ms | H25: FALSE | I25: FALSE | K25: tc | L25: FALSE | M25: FALSE | O25: jc | P25: TRUE | Q25: TRUE | R25: TRUE | S25: FALSE | U25: TRUE | V25: TRUE | W25: FALSE | X25: FALSE
G26: o | H26: TRUE | I26: TRUE | K26: u | L26: FALSE | M26: FALSE | O26: k | P26: TRUE | Q26: TRUE | R26: TRUE | S26: FALSE | U26: TRUE | V26: TRUE | W26: FALSE | X26: FALSE
G27: od | H27: TRUE | I27: TRUE | K27: uc | L27: FALSE | M27: FALSE | O27: l | P27: TRUE | Q27: TRUE | R27: TRUE | S27: FALSE | U27: TRUE | V27: TRUE | W27: FALSE | X27: FALSE
G28: of | H28: TRUE | I28: TRUE | K28: x | L28: FALSE | M28: FALSE | O28: lf | P28: TRUE | Q28: TRUE | R28: TRUE | S28: FALSE | U28: TRUE | V28: TRUE | W28: FALSE | X28: FALSE
G29: r | H29: TRUE | I29: TRUE | K29: xc | L29: FALSE | M29: FALSE | O29: m | P29: TRUE | Q29: TRUE | R29: TRUE | S29: FALSE | U29: TRUE | V29: TRUE | W29: FALSE | X29: FALSE
G30: rd | H30: TRUE | I30: TRUE | O30: ms | P30: TRUE | Q30: TRUE | R30: TRUE | S30: FALSE | U30: TRUE | V30: TRUE | W30: FALSE | X30: FALSE
G31: v | H31: FALSE | I31: FALSE | O31: o | P31: TRUE | Q31: TRUE | R31: TRUE | S31: FALSE | U31: TRUE | V31: TRUE | W31: FALSE | X31: FALSE
G32: w | H32: TRUE | I32: TRUE | O32: od | P32: TRUE | Q32: TRUE | R32: TRUE | S32: FALSE | U32: TRUE | V32: TRUE | W32: FALSE | X32: FALSE
G33: wd | H33: TRUE | I33: TRUE | O33: of | P33: TRUE | Q33: TRUE | R33: TRUE | S33: FALSE | U33: TRUE | V33: TRUE | W33: FALSE | X33: FALSE
G34: z | H34: TRUE | I34: TRUE | O34: r | P34: TRUE | Q34: TRUE | R34: TRUE | S34: FALSE | U34: TRUE | V34: TRUE | W34: FALSE | X34: FALSE
G35: zd | H35: TRUE | I35: TRUE | O35: rd | P35: TRUE | Q35: TRUE | R35: TRUE | S35: FALSE | U35: TRUE | V35: TRUE | W35: FALSE | X35: FALSE
O36: s | P36: TRUE | Q36: TRUE | R36: TRUE | S36: FALSE | U36: TRUE | V36: TRUE | W36: FALSE | X36: FALSE
O37: sp | P37: TRUE | Q37: TRUE | R37: TRUE | S37: FALSE | U37: TRUE | V37: TRUE | W37: FALSE | X37: FALSE
O38: t | P38: TRUE | Q38: TRUE | R38: TRUE | S38: FALSE | U38: TRUE | V38: TRUE | W38: FALSE | X38: FALSE
O39: tc | P39: TRUE | Q39: TRUE | R39: TRUE | S39: FALSE | U39: TRUE | V39: TRUE | W39: FALSE | X39: FALSE
O40: u | P40: TRUE | Q40: TRUE | R40: TRUE | S40: FALSE | U40: TRUE | V40: TRUE | W40: FALSE | X40: FALSE
O41: uc | P41: TRUE | Q41: TRUE | R41: TRUE | S41: FALSE | U41: TRUE | V41: TRUE | W41: FALSE | X41: FALSE
O42: v | P42: TRUE | Q42: TRUE | R42: TRUE | S42: FALSE | U42: TRUE | V42: TRUE | W42: FALSE | X42: FALSE
O43: w | P43: TRUE | Q43: TRUE | R43: TRUE | S43: FALSE | U43: TRUE | V43: TRUE | W43: FALSE | X43: FALSE
O44: wd | P44: TRUE | Q44: TRUE | R44: TRUE | S44: FALSE | U44: TRUE | V44: TRUE | W44: FALSE | X44: FALSE
O45: x | P45: TRUE | Q45: TRUE | R45: TRUE | S45: FALSE | U45: TRUE | V45: TRUE | W45: FALSE | X45: FALSE
O46: xc | P46: TRUE | Q46: TRUE | R46: TRUE | S46: FALSE | U46: TRUE | V46: TRUE | W46: FALSE | X46: FALSE
O47: z | P47: TRUE | Q47: TRUE | R47: TRUE | S47: FALSE | U47: TRUE | V47: TRUE | W47: FALSE | X47: FALSE
...

Sheet Sup Feed
C3: «
E4: Däta | G4: LIVESTOCK FEEDS - FEED STORAGE CAPITAL COSTS
G5: Cost Item x Storage Type
G6: 43614 | I6: *Auger depriciation is accounted for in Mach sheet
C7: 0
J10: Grain Silo | K10: Hay Shed
J13: grain | K13: hay
I14: capacity | J14: 70 | K14: 120
I15: price | J15: 4760 | K15: 6752 | L15: $ | M15: *start price and end price are probably a bit low?
I16: life | J16: 30 | K16: 30 | L16: Years
I17: salvage value | J17: =J15/EXP(J16*LN(1.2)) -> 20.052548 | K17: =K15/EXP(K16*LN(1.2)) -> 28.444287 | L17: $
I18: other | J18: 3.6 | K18: 0 | L18: $/t
G20: =G4 -> LIVESTOCK FEEDS - FEED STORAGE CAPITAL COSTS | W20: »
C23: «
E24: Däta | G24: LIVESTOCK FEEDS - CONFINEMENT INFRASTRUCTURE COSTS
G26: 43909
C27: 0
K31: Dep - fixed | N31: R&M - variable
J32: price | K32: 15000 | L32: $ | N32: 4.5 | O32: $/t
J33: life | K33: 30 | L33: Years
J34: salvage value | K34: =K32/EXP(K33*LN(1.2)) -> 63.190803 | L34: $
G36: =G24 -> LIVESTOCK FEEDS - CONFINEMENT INFRASTRUCTURE COSTS | W36: »
C40: «
E41: Däta | G41: LIVESTOCK FEEDS - STORAGE COSTS
G42: Date to incur variable costs
G43: 43909
C44: 0
J49: date | K49: =MIN(364,INT((L49 - DATE(YEAR(L49),1,1)))) -> 341 | L49: 43807
G52: =G41 -> LIVESTOCK FEEDS - STORAGE COSTS | W52: »
C55: « | D55: 969.17525
D56: -40.80873 | E56: Däta | G56: LABOUR GRAIN FEEDING - LABOUR REQUIREMENT FOR GRAIN FEEDING SHEEP
G57: Filling & Emptying the Feeder
G58: 37780.587
C59: 1 | G59: Revised? | K59: info
K62: Time required to feed
K63: hrs/t
G65: Filling sheep feeder & get to paddock
H67: grain | I67: hay
G68: drive time | H68: 0.1 | I68: 0.2 | J68: hr | K68: =H68*60 -> 6 | L68: =I68*60 -> 12 | M68: mins
G69: fill time | H69: 0.1 | I69: 0.1 | J69: hr/load | K69: =H69*60 -> 6 | L69: =I69*60 -> 6 | M69: mins
...

Sheet Crop
C3: «
E4: Däta | G4: Improvements
C17: 0
C22: «
E23: Däta | G23: General info
C26: 0
G31: grain income date | H31: =MIN(364,INT((I31 - DATE(YEAR(I31),1,1)))) -> 348 | I31: 43814 | J31: =IF(i_grain_income_date>MAX($U$99:$AD$117),"","**ERROR**")
G33: peak debt date | H33: =$H$31-7 -> 341
G34: cashflow date | H34: =$H$31+7 -> 355
G35: crop c0 inc | H35: TRUE
G37: Dry seeding
H38: dry seed start | I38: =MIN(51,INT((J38 - DATE(YEAR(J38),1,1))/7))*7 -> 91 | J38: 43560 | K38: =IF(dry_seed_start<MIN(General!i_date_node_zm),"**ERROR**","")
G41: Seeding Penalty
G43: seeding_penalty | I43: =I44 -> 91 | J43: =J44 -> 98 | K43: =K44 -> 105 | L43: =L44 -> 112 | M43: =M44 -> 119 | N43: =N44 -> 126 | O43: =O44 -> 133 | P43: =P44 -> 140
H44: landuse | I44: =dry_seed_start -> 91 | J44: =I44+7 -> 98 | K44: =J44+7 -> 105 | L44: =K44+7 -> 112 | M44: =L44+7 -> 119 | N44: =M44+7 -> 126 | O44: =N44+7 -> 133 | P44: =O44+7 -> 140
H45: =General!G17 -> b | I45: 13.367143 | J45: 13.367143 | K45: 6.3685714 | L45: 5.46 | M45: 0 | N45: 0 | O45: -17.554286 | P45: -21.865714
H46: =General!G18 -> bd | I46: 13.367143 | J46: 13.367143 | K46: 6.3685714 | L46: 5.46 | M46: 0 | N46: 0 | O46: -17.554286 | P46: -21.865714
H47: =General!G19 -> f | I47: 0 | J47: 0 | K47: 0 | L47: 0 | M47: 0 | N47: 0 | O47: -27.717429 | P47: -32.673429
H48: =General!G20 -> h | I48: 13.367143 | J48: 13.367143 | K48: 6.3685714 | L48: 5.46 | M48: 0 | N48: 0 | O48: -17.554286 | P48: -21.865714
H49: =General!G21 -> i | I49: 0 | J49: 0 | K49: 0 | L49: 0 | M49: 0 | N49: 0 | O49: -27.717429 | P49: -32.673429
H50: =General!G22 -> k | I50: 0 | J50: 0 | K50: 0 | L50: 0 | M50: 0 | N50: 0 | O50: -27.717429 | P50: -32.673429
H51: =General!G23 -> l | I51: 0 | J51: 0 | K51: 0 | L51: 0 | M51: 0 | N51: 0 | O51: -27.717429 | P51: -32.673429
H52: =General!G24 -> lf | I52: 0 | J52: 0 | K52: 0 | L52: 0 | M52: 0 | N52: 0 | O52: -27.717429 | P52: -32.673429
H53: =General!G25 -> ms | I53: =0.215*I45+0.215*I60+0.215*I47+0.215*I51+0.14*I62 -> 5.7478714 | J53: =0.215*J45+0.215*J60+0.215*J47+0.215*J51+0.14*J62 -> 5.7478714 | K53: =0.215*K45+0.215*K60+0.215*K47+0.215*K51+0.14*K62 -> 2.7384857 | L53: =0.215*L45+0.215*L60+0.215*L47+0.215*L51+0.14*L62 -> 2.3478 | M53: =0.215*M45+0.215*M60+0.215*M47+0.215*M51+0.14*M62 -> 0 | N53: =0.215*N45+0.215*N60+0.215*N47+0.215*N51+0.14*N62 -> 0 | O53: =0.215*O45+0.215*O60+0.215*O47+0.215*O51+0.14*O62 -> -23.347277 | P53: =0.215*P45+0.215*P60+0.215*P47+0.215*P51+0.14*P62 -> -28.026111
H54: =General!G26 -> o | I54: 13.367143 | J54: 13.367143 | K54: 6.3685714 | L54: 5.46 | M54: 0 | N54: 0 | O54: -17.554286 | P54: -21.865714
H55: =General!G27 -> od | I55: 13.367143 | J55: 13.367143 | K55: 6.3685714 | L55: 5.46 | M55: 0 | N55: 0 | O55: -17.554286 | P55: -21.865714
H56: =General!G28 -> of | I56: 13.367143 | J56: 13.367143 | K56: 6.3685714 | L56: 5.46 | M56: 0 | N56: 0 | O56: -17.554286 | P56: -21.865714
H57: =General!G29 -> r | I57: 0 | J57: 0 | K57: 0 | L57: 0 | M57: 0 | N57: 0 | O57: -27.717429 | P57: -32.673429
H58: =General!G30 -> rd | I58: 0 | J58: 0 | K58: 0 | L58: 0 | M58: 0 | N58: 0 | O58: -27.717429 | P58: -32.673429
H59: =General!G31 -> v | I59: 0 | J59: 0 | K59: 0 | L59: 0 | M59: 0 | N59: 0 | O59: -27.717429 | P59: -32.673429
H60: =General!G32 -> w | I60: 13.367143 | J60: 13.367143 | K60: 6.3685714 | L60: 5.46 | M60: 0 | N60: 0 | O60: -17.554286 | P60: -21.865714
H61: =General!G33 -> wd | I61: 13.367143 | J61: 13.367143 | K61: 6.3685714 | L61: 5.46 | M61: 0 | N61: 0 | O61: -17.554286 | P61: -21.865714
H62: =General!G34 -> z | I62: 0 | J62: 0 | K62: 0 | L62: 0 | M62: 0 | N62: 0 | O62: -27.717429 | P62: -32.673429
H63: =General!G35 -> zd | I63: 0 | J63: 0 | K63: 0 | L63: 0 | M63: 0 | N63: 0 | O63: -27.717429 | P63: -32.673429
H65: lmu | I65: =I44 -> 91 | J65: =J44 -> 98 | K65: =K44 -> 105 | L65: =L44 -> 112 | M65: =M44 -> 119 | N65: =N44 -> 126 | O65: =O44 -> 133 | P65: =P44 -> 140
H66: lmu0 | I66: 1 | J66: 1 | K66: 1 | L66: 1 | M66: 1 | N66: 1 | O66: 1 | P66: 1
H67: lmu1 | I67: 1 | J67: 1 | K67: 1 | L67: 1 | M67: 1 | N67: 1 | O67: 1 | P67: 1
H68: lmu2 | I68: 1 | J68: 1 | K68: 1 | L68: 1 | M68: 1 | N68: 1 | O68: 1 | P68: 1
H69: lmu3 | I69: 1 | J69: 1 | K69: 1 | L69: 1 | M69: 1 | N69: 1 | O69: 1 | P69: 1
H70: lmu4 | I70: 1 | J70: 1 | K70: 1 | L70: 1 | M70: 1 | N70: 1 | O70: 1 | P70: 1
...

Sheet Emissions
C3: «
E4: Däta | G4: Annual Electricity Use (State Grid)
H6: 4000 | I6: KWh
G10: =G4 -> Annual Electricity Use (State Grid) | W10: »
C14: «
E15: Däta | G15: Leaching factor rainfal adjuster
G17: Does your farm get enough rainfall or irrigation to drain through the soil profile i.e. typically above 600mm
H18: FALSE
G21: =G15 -> Leaching factor rainfal adjuster | W21: »
C25: «
E26: Däta | G26: Residue Burning
H27: Date of residue burning | M27: Proportion of harvested area that is burnt - Acording to GRDC survey 2021
H28: =MIN(364,INT((I28 - DATE(YEAR(I28),1,1)))) -> 59 | I28: 43525 | L28: =General!G17 -> b | M28: 0.04
L29: =General!G18 -> bd | M29: 0.04
L30: =General!G19 -> f | M30: 0.04
L31: =General!G20 -> h | M31: 0.04
L32: =General!G21 -> i | M32: 0.04
L33: =General!G22 -> k | M33: 0.04
L34: =General!G23 -> l | M34: 0.04
L35: =General!G24 -> lf | M35: 0.04
L36: =General!G25 -> ms | M36: 0.04
L37: =General!G26 -> o | M37: 0.04
L38: =General!G27 -> od | M38: 0.04
L39: =General!G28 -> of | M39: 0.04
L40: =General!G29 -> r | M40: 0.04
... L46: =General!G35 -> zd | M46: 0.04
G51: =G26 -> Residue Burning | W51: »

Sheet CropGrazing
G4: Crop Grazing included
H5: TRUE
G9: =G4 -> Crop Grazing included
C12: «
E13: Däta | G13: Proportion of area that can be grazed
C16: 0
G20: Landuse | H20: lmu0 | I20: lmu1 | J20: lmu2 | K20: lmu3 | L20: lmu4 | M20: lmu5 | N20: lmu6 | O20: lmu7 | P20: lmu8
G21: =General!G17 -> b | H21: 1 | I21: 1 | J21: 1 | K21: 1 | L21: 1 | M21: 1 | N21: 1 | O21: 1 | P21: 1
G22: =General!G18 -> bd | H22: 1 | I22: 1 | J22: 1 | K22: 1 | L22: 1 | M22: 1 | N22: 1 | O22: 1 | P22: 1
G23: =General!G19 -> f | H23: 1 | I23: 1 | J23: 1 | K23: 1 | L23: 1 | M23: 1 | N23: 1 | O23: 1 | P23: 1
G24: =General!G20 -> h | H24: 1 | I24: 1 | J24: 1 | K24: 1 | L24: 1 | M24: 1 | N24: 1 | O24: 1 | P24: 1
G25: =General!G21 -> i | H25: 1 | I25: 1 | J25: 1 | K25: 1 | L25: 1 | M25: 1 | N25: 1 | O25: 1 | P25: 1
G26: =General!G22 -> k | H26: 1 | I26: 1 | J26: 1 | K26: 1 | L26: 1 | M26: 1 | N26: 1 | O26: 1 | P26: 1
G27: =General!G23 -> l | H27: 1 | I27: 1 | J27: 1 | K27: 1 | L27: 1 | M27: 1 | N27: 1 | O27: 1 | P27: 1
G28: =General!G24 -> lf | H28: 1 | I28: 1 | J28: 1 | K28: 1 | L28: 1 | M28: 1 | N28: 1 | O28: 1 | P28: 1
G29: =General!G25 -> ms | H29: 1 | I29: 1 | J29: 1 | K29: 1 | L29: 1 | M29: 1 | N29: 1 | O29: 1 | P29: 1
G30: =General!G26 -> o | H30: 1 | I30: 1 | J30: 1 | K30: 1 | L30: 1 | M30: 1 | N30: 1 | O30: 1 | P30: 1
G31: =General!G27 -> od | H31: 1 | I31: 1 | J31: 1 | K31: 1 | L31: 1 | M31: 1 | N31: 1 | O31: 1 | P31: 1
G32: =General!G28 -> of | H32: 1 | I32: 1 | J32: 1 | K32: 1 | L32: 1 | M32: 1 | N32: 1 | O32: 1 | P32: 1
... G39: =General!G35 -> zd | H39: 1 | I39: 1 | J39: 1 | K39: 1 | L39: 1 | M39: 1 | N39: 1 | O39: 1 | P39: 1
G44: =G13 -> Proportion of area that can be grazed | W44: »
C47: « | D47: =SUM(F72:V112) -> 1213.204
D48: 80 | E48: Däta | G48: GRAZING CROPS - ESTIMATED GROWTH RATE & CONSUMPTION
D49: =OR(ISNA(VLOOKUP(G48,Index_Table_Names,1,FALSE)),G48="") -> FALSE
D50: =(D48<>D47) -> TRUE | H50: Days after sowing grazing can occur | K50: 30
G52: Height Ratio
D53: 80 | E53: Däta | J53: HR | K53: 1
D54: =OR(ISNA(VLOOKUP(G53,Index_Table_Names,1,FALSE)),G53="") -> TRUE
D55: =(D53<>#REF!) -> #REF!
G56: Propn of growth that can be consumed | K56: P0 | L56: P1 | M56: P2 | N56: P3 | O56: P4 | P56: P5 | Q56: P6 | R56: P7 | S56: P8 | T56: P9
D57: 80 | E57: Däta | J57: typ | K57: 0 | L57: 0.21 | M57: 0.21 | N57: 0 | O57: 0 | P57: 0 | Q57: 0 | R57: 0 | S57: 0 | T57: 0
J58: z0 | K58: 0 | L58: 0.21 | M58: 0.21 | N58: 0 | O58: 0 | P58: 0 | Q58: 0 | R58: 0 | S58: 0 | T58: 0
J59: z1 | K59: 0 | L59: 0.21 | M59: 0.21 | N59: 0 | O59: 0 | P59: 0 | Q59: 0 | R59: 0 | S59: 0 | T59: 0
J60: z2 | K60: 0 | L60: 0.21 | M60: 0 | N60: 0 | O60: 0 | P60: 0 | Q60: 0 | R60: 0 | S60: 0 | T60: 0
J61: z3 | K61: 0 | L61: 0.21 | M61: 0 | N61: 0 | O61: 0 | P61: 0 | Q61: 0 | R61: 0 | S61: 0 | T61: 0
J62: z4 | K62: 0 | L62: 0.21 | M62: 0.21 | N62: 0 | O62: 0 | P62: 0 | Q62: 0 | R62: 0 | S62: 0 | T62: 0
J63: z5 | K63: 0 | L63: 0.21 | M63: 0.21 | N63: 0 | O63: 0 | P63: 0 | Q63: 0 | R63: 0 | S63: 0 | T63: 0
J64: z6 | K64: 0 | L64: 0.21 | M64: 0 | N64: 0 | O64: 0 | P64: 0 | Q64: 0 | R64: 0 | S64: 0 | T64: 0
J65: z7 | K65: 0 | L65: 0.21 | M65: 0 | N65: 0 | O65: 0 | P65: 0 | Q65: 0 | R65: 0 | S65: 0 | T65: 0
J66: z8 | K66: 0 | L66: 0.21 | M66: 0.21 | N66: 0 | O66: 0 | P66: 0 | Q66: 0 | R66: 0 | S66: 0 | T66: 0
...

Sheet Periods
E4: Stocashtic Feed Periods
U18: Day of yr - input for AFO
E20: period | F20: typ | G20: season0 | H20: season1 | I20: season2 | J20: season3 | K20: season4 | L20: season5 | M20: season6 | N20: season7 | O20: season8 | T20: period | U20: typ | V20: season0 | W20: season1 | X20: season2 | Y20: season3 | Z20: season4 | AA20: season5 | AB20: season6 | AC20: season7 | AD20: season8
E21: FP0 | F21: 43560 | G21: 43560 | H21: =G21 -> 43560 | I21: =H21 -> 43560 | J21: =G21 -> 43560 | K21: =J21 -> 43560 | L21: =K21 -> 43560 | M21: =J21 -> 43560 | N21: =M21 -> 43560 | O21: =N21 -> 43560 | P21: First feed period is the start of the season (beginning of dry seeding) | T21: FP0 | U21: =MIN(51,INT((F21 - DATE(YEAR(F21),1,1))/7))*7+IF(YEAR(F21)>YEAR(F$21),364,0) -> 91 | V21: =MIN(51,INT((G21 - DATE(YEAR(G21),1,1))/7))*7+IF(YEAR(G21)>YEAR(G$21),364,0) -> 91 | W21: =MIN(51,INT((H21 - DATE(YEAR(H21),1,1))/7))*7+IF(YEAR(H21)>YEAR(H$21),364,0) -> 91 | X21: =MIN(51,INT((I21 - DATE(YEAR(I21),1,1))/7))*7+IF(YEAR(I21)>YEAR(I$21),364,0) -> 91 | Y21: =MIN(51,INT((J21 - DATE(YEAR(J21),1,1))/7))*7+IF(YEAR(J21)>YEAR(J$21),364,0) -> 91 | Z21: =MIN(51,INT((K21 - DATE(YEAR(K21),1,1))/7))*7+IF(YEAR(K21)>YEAR(K$21),364,0) -> 91 | AA21: =MIN(51,INT((L21 - DATE(YEAR(L21),1,1))/7))*7+IF(YEAR(L21)>YEAR(L$21),364,0) -> 91 | AB21: =MIN(51,INT((M21 - DATE(YEAR(M21),1,1))/7))*7+IF(YEAR(M21)>YEAR(M$21),364,0) -> 91 | ... AD21: =MIN(51,INT((O21 - DATE(YEAR(O21),1,1))/7))*7+IF(YEAR(O21)>YEAR(O$21),364,0) -> 91
E22: FP1 | F22: 43600 | G22: 43589 | H22: =G22 -> 43589 | I22: =H22 -> 43589 | J22: =I22 -> 43589 | K22: 43606 | L22: =K22 -> 43606 | M22: =K22 -> 43606 | N22: =M22 -> 43606 | O22: =N22 -> 43606 | T22: FP1 | U22: =MIN(51,INT((F22 - DATE(YEAR(F22),1,1))/7))*7+IF(YEAR(F22)>YEAR(F$21),364,0) -> 133 | V22: =MIN(51,INT((G22 - DATE(YEAR(G22),1,1))/7))*7+IF(YEAR(G22)>YEAR(G$21),364,0) -> 119 | W22: =MIN(51,INT((H22 - DATE(YEAR(H22),1,1))/7))*7+IF(YEAR(H22)>YEAR(H$21),364,0) -> 119 | X22: =MIN(51,INT((I22 - DATE(YEAR(I22),1,1))/7))*7+IF(YEAR(I22)>YEAR(I$21),364,0) -> 119 | Y22: =MIN(51,INT((J22 - DATE(YEAR(J22),1,1))/7))*7+IF(YEAR(J22)>YEAR(J$21),364,0) -> 119 | Z22: =MIN(51,INT((K22 - DATE(YEAR(K22),1,1))/7))*7+IF(YEAR(K22)>YEAR(K$21),364,0) -> 140 | AA22: =MIN(51,INT((L22 - DATE(YEAR(L22),1,1))/7))*7+IF(YEAR(L22)>YEAR(L$21),364,0) -> 140 | AB22: =MIN(51,INT((M22 - DATE(YEAR(M22),1,1))/7))*7+IF(YEAR(M22)>YEAR(M$21),364,0) -> 140 | ... AD22: =MIN(51,INT((O22 - DATE(YEAR(O22),1,1))/7))*7+IF(YEAR(O22)>YEAR(O$21),364,0) -> 140
E23: FP2 | F23: 43631 | G23: 43631 | H23: =G23 -> 43631 | I23: =H23 -> 43631 | J23: =I23 -> 43631 | K23: =J23 -> 43631 | L23: =K23 -> 43631 | M23: =L23 -> 43631 | N23: =M23 -> 43631 | O23: =N23 -> 43631 | T23: FP2 | U23: =MIN(51,INT((F23 - DATE(YEAR(F23),1,1))/7))*7+IF(YEAR(F23)>YEAR(F$21),364,0) -> 161 | V23: =MIN(51,INT((G23 - DATE(YEAR(G23),1,1))/7))*7+IF(YEAR(G23)>YEAR(G$21),364,0) -> 161 | W23: =MIN(51,INT((H23 - DATE(YEAR(H23),1,1))/7))*7+IF(YEAR(H23)>YEAR(H$21),364,0) -> 161 | X23: =MIN(51,INT((I23 - DATE(YEAR(I23),1,1))/7))*7+IF(YEAR(I23)>YEAR(I$21),364,0) -> 161 | Y23: =MIN(51,INT((J23 - DATE(YEAR(J23),1,1))/7))*7+IF(YEAR(J23)>YEAR(J$21),364,0) -> 161 | Z23: =MIN(51,INT((K23 - DATE(YEAR(K23),1,1))/7))*7+IF(YEAR(K23)>YEAR(K$21),364,0) -> 161 | AA23: =MIN(51,INT((L23 - DATE(YEAR(L23),1,1))/7))*7+IF(YEAR(L23)>YEAR(L$21),364,0) -> 161 | AB23: =MIN(51,INT((M23 - DATE(YEAR(M23),1,1))/7))*7+IF(YEAR(M23)>YEAR(M$21),364,0) -> 161 | ... AD23: =MIN(51,INT((O23 - DATE(YEAR(O23),1,1))/7))*7+IF(YEAR(O23)>YEAR(O$21),364,0) -> 161
E24: FP3 | F24: 43684 | G24: 43684 | H24: =G24 -> 43684 | I24: 43684 | J24: =I24 -> 43684 | K24: 43684 | L24: =K24 -> 43684 | M24: 43684 | N24: =M24 -> 43684 | O24: =N24 -> 43684 | T24: FP3 | U24: =MIN(51,INT((F24 - DATE(YEAR(F24),1,1))/7))*7+IF(YEAR(F24)>YEAR(F$21),364,0) -> 217 | V24: =MIN(51,INT((G24 - DATE(YEAR(G24),1,1))/7))*7+IF(YEAR(G24)>YEAR(G$21),364,0) -> 217 | W24: =MIN(51,INT((H24 - DATE(YEAR(H24),1,1))/7))*7+IF(YEAR(H24)>YEAR(H$21),364,0) -> 217 | X24: =MIN(51,INT((I24 - DATE(YEAR(I24),1,1))/7))*7+IF(YEAR(I24)>YEAR(I$21),364,0) -> 217 | Y24: =MIN(51,INT((J24 - DATE(YEAR(J24),1,1))/7))*7+IF(YEAR(J24)>YEAR(J$21),364,0) -> 217 | Z24: =MIN(51,INT((K24 - DATE(YEAR(K24),1,1))/7))*7+IF(YEAR(K24)>YEAR(K$21),364,0) -> 217 | AA24: =MIN(51,INT((L24 - DATE(YEAR(L24),1,1))/7))*7+IF(YEAR(L24)>YEAR(L$21),364,0) -> 217 | AB24: =MIN(51,INT((M24 - DATE(YEAR(M24),1,1))/7))*7+IF(YEAR(M24)>YEAR(M$21),364,0) -> 217 | ... AD24: =MIN(51,INT((O24 - DATE(YEAR(O24),1,1))/7))*7+IF(YEAR(O24)>YEAR(O$21),364,0) -> 217
E25: FP4 | F25: 43709 | G25: 43709 | H25: =G25 -> 43709 | I25: =H25 -> 43709 | J25: =I25 -> 43709 | K25: =J25 -> 43709 | L25: =K25 -> 43709 | M25: =L25 -> 43709 | N25: =M25 -> 43709 | O25: =N25 -> 43709 | T25: FP4 | U25: =MIN(51,INT((F25 - DATE(YEAR(F25),1,1))/7))*7+IF(YEAR(F25)>YEAR(F$21),364,0) -> 238 | V25: =MIN(51,INT((G25 - DATE(YEAR(G25),1,1))/7))*7+IF(YEAR(G25)>YEAR(G$21),364,0) -> 238 | W25: =MIN(51,INT((H25 - DATE(YEAR(H25),1,1))/7))*7+IF(YEAR(H25)>YEAR(H$21),364,0) -> 238 | X25: =MIN(51,INT((I25 - DATE(YEAR(I25),1,1))/7))*7+IF(YEAR(I25)>YEAR(I$21),364,0) -> 238 | Y25: =MIN(51,INT((J25 - DATE(YEAR(J25),1,1))/7))*7+IF(YEAR(J25)>YEAR(J$21),364,0) -> 238 | Z25: =MIN(51,INT((K25 - DATE(YEAR(K25),1,1))/7))*7+IF(YEAR(K25)>YEAR(K$21),364,0) -> 238 | AA25: =MIN(51,INT((L25 - DATE(YEAR(L25),1,1))/7))*7+IF(YEAR(L25)>YEAR(L$21),364,0) -> 238 | AB25: =MIN(51,INT((M25 - DATE(YEAR(M25),1,1))/7))*7+IF(YEAR(M25)>YEAR(M$21),364,0) -> 238 | ... AD25: =MIN(51,INT((O25 - DATE(YEAR(O25),1,1))/7))*7+IF(YEAR(O25)>YEAR(O$21),364,0) -> 238
E26: FP5 | F26: 43738 | G26: 43738 | H26: =F26 -> 43738 | I26: =G26 -> 43738 | J26: =H26 -> 43738 | K26: 43738 | L26: =J26 -> 43738 | M26: =K26 -> 43738 | N26: =L26 -> 43738 | O26: =N26 -> 43738 | T26: FP5 | U26: =MIN(51,INT((F26 - DATE(YEAR(F26),1,1))/7))*7+IF(YEAR(F26)>YEAR(F$21),364,0) -> 266 | V26: =MIN(51,INT((G26 - DATE(YEAR(G26),1,1))/7))*7+IF(YEAR(G26)>YEAR(G$21),364,0) -> 266 | W26: =MIN(51,INT((H26 - DATE(YEAR(H26),1,1))/7))*7+IF(YEAR(H26)>YEAR(H$21),364,0) -> 266 | X26: =MIN(51,INT((I26 - DATE(YEAR(I26),1,1))/7))*7+IF(YEAR(I26)>YEAR(I$21),364,0) -> 266 | Y26: =MIN(51,INT((J26 - DATE(YEAR(J26),1,1))/7))*7+IF(YEAR(J26)>YEAR(J$21),364,0) -> 266 | Z26: =MIN(51,INT((K26 - DATE(YEAR(K26),1,1))/7))*7+IF(YEAR(K26)>YEAR(K$21),364,0) -> 266 | AA26: =MIN(51,INT((L26 - DATE(YEAR(L26),1,1))/7))*7+IF(YEAR(L26)>YEAR(L$21),364,0) -> 266 | AB26: =MIN(51,INT((M26 - DATE(YEAR(M26),1,1))/7))*7+IF(YEAR(M26)>YEAR(M$21),364,0) -> 266 | ... AD26: =MIN(51,INT((O26 - DATE(YEAR(O26),1,1))/7))*7+IF(YEAR(O26)>YEAR(O$21),364,0) -> 266
E27: FP6 | F27: 43753 | G27: 43758 | H27: =G27 -> 43758 | I27: =H27 -> 43758 | J27: =I27 -> 43758 | K27: 43748 | L27: =K27 -> 43748 | M27: =L27 -> 43748 | N27: =M27 -> 43748 | O27: =N27 -> 43748 | T27: FP6 | U27: =MIN(51,INT((F27 - DATE(YEAR(F27),1,1))/7))*7+IF(YEAR(F27)>YEAR(F$21),364,0) -> 287 | V27: =MIN(51,INT((G27 - DATE(YEAR(G27),1,1))/7))*7+IF(YEAR(G27)>YEAR(G$21),364,0) -> 287 | W27: =MIN(51,INT((H27 - DATE(YEAR(H27),1,1))/7))*7+IF(YEAR(H27)>YEAR(H$21),364,0) -> 287 | X27: =MIN(51,INT((I27 - DATE(YEAR(I27),1,1))/7))*7+IF(YEAR(I27)>YEAR(I$21),364,0) -> 287 | Y27: =MIN(51,INT((J27 - DATE(YEAR(J27),1,1))/7))*7+IF(YEAR(J27)>YEAR(J$21),364,0) -> 287 | Z27: =MIN(51,INT((K27 - DATE(YEAR(K27),1,1))/7))*7+IF(YEAR(K27)>YEAR(K$21),364,0) -> 280 | AA27: =MIN(51,INT((L27 - DATE(YEAR(L27),1,1))/7))*7+IF(YEAR(L27)>YEAR(L$21),364,0) -> 280 | AB27: =MIN(51,INT((M27 - DATE(YEAR(M27),1,1))/7))*7+IF(YEAR(M27)>YEAR(M$21),364,0) -> 280 | ... AD27: =MIN(51,INT((O27 - DATE(YEAR(O27),1,1))/7))*7+IF(YEAR(O27)>YEAR(O$21),364,0) -> 280
E28: FP7 | F28: 43794 | G28: 43794 | H28: =G28 -> 43794 | I28: =H28 -> 43794 | J28: =I28 -> 43794 | K28: =J28 -> 43794 | L28: =K28 -> 43794 | M28: =L28 -> 43794 | N28: =M28 -> 43794 | O28: =N28 -> 43794 | T28: FP7 | U28: =MIN(51,INT((F28 - DATE(YEAR(F28),1,1))/7))*7+IF(YEAR(F28)>YEAR(F$21),364,0) -> 322 | V28: =MIN(51,INT((G28 - DATE(YEAR(G28),1,1))/7))*7+IF(YEAR(G28)>YEAR(G$21),364,0) -> 322 | W28: =MIN(51,INT((H28 - DATE(YEAR(H28),1,1))/7))*7+IF(YEAR(H28)>YEAR(H$21),364,0) -> 322 | X28: =MIN(51,INT((I28 - DATE(YEAR(I28),1,1))/7))*7+IF(YEAR(I28)>YEAR(I$21),364,0) -> 322 | Y28: =MIN(51,INT((J28 - DATE(YEAR(J28),1,1))/7))*7+IF(YEAR(J28)>YEAR(J$21),364,0) -> 322 | Z28: =MIN(51,INT((K28 - DATE(YEAR(K28),1,1))/7))*7+IF(YEAR(K28)>YEAR(K$21),364,0) -> 322 | AA28: =MIN(51,INT((L28 - DATE(YEAR(L28),1,1))/7))*7+IF(YEAR(L28)>YEAR(L$21),364,0) -> 322 | AB28: =MIN(51,INT((M28 - DATE(YEAR(M28),1,1))/7))*7+IF(YEAR(M28)>YEAR(M$21),364,0) -> 322 | ... AD28: =MIN(51,INT((O28 - DATE(YEAR(O28),1,1))/7))*7+IF(YEAR(O28)>YEAR(O$21),364,0) -> 322
E29: FP8 | F29: 43831 | G29: 43831 | H29: =G29 -> 43831 | I29: =H29 -> 43831 | J29: =I29 -> 43831 | K29: =J29 -> 43831 | L29: =K29 -> 43831 | M29: =L29 -> 43831 | N29: =M29 -> 43831 | O29: =N29 -> 43831 | T29: FP8 | U29: =MIN(51,INT((F29 - DATE(YEAR(F29),1,1))/7))*7+IF(YEAR(F29)>YEAR(F$21),364,0) -> 364 | V29: =MIN(51,INT((G29 - DATE(YEAR(G29),1,1))/7))*7+IF(YEAR(G29)>YEAR(G$21),364,0) -> 364 | W29: =MIN(51,INT((H29 - DATE(YEAR(H29),1,1))/7))*7+IF(YEAR(H29)>YEAR(H$21),364,0) -> 364 | X29: =MIN(51,INT((I29 - DATE(YEAR(I29),1,1))/7))*7+IF(YEAR(I29)>YEAR(I$21),364,0) -> 364 | Y29: =MIN(51,INT((J29 - DATE(YEAR(J29),1,1))/7))*7+IF(YEAR(J29)>YEAR(J$21),364,0) -> 364 | Z29: =MIN(51,INT((K29 - DATE(YEAR(K29),1,1))/7))*7+IF(YEAR(K29)>YEAR(K$21),364,0) -> 364 | AA29: =MIN(51,INT((L29 - DATE(YEAR(L29),1,1))/7))*7+IF(YEAR(L29)>YEAR(L$21),364,0) -> 364 | AB29: =MIN(51,INT((M29 - DATE(YEAR(M29),1,1))/7))*7+IF(YEAR(M29)>YEAR(M$21),364,0) -> 364 | ... AD29: =MIN(51,INT((O29 - DATE(YEAR(O29),1,1))/7))*7+IF(YEAR(O29)>YEAR(O$21),364,0) -> 364
E30: FP9 | F30: 43876 | G30: 43876 | H30: =G30 -> 43876 | I30: =H30 -> 43876 | J30: =I30 -> 43876 | K30: =J30 -> 43876 | L30: =K30 -> 43876 | M30: =L30 -> 43876 | N30: =M30 -> 43876 | O30: =N30 -> 43876 | T30: FP9 | U30: =MIN(51,INT((F30 - DATE(YEAR(F30),1,1))/7))*7+IF(YEAR(F30)>YEAR(F$21),364,0) -> 406 | V30: =MIN(51,INT((G30 - DATE(YEAR(G30),1,1))/7))*7+IF(YEAR(G30)>YEAR(G$21),364,0) -> 406 | W30: =MIN(51,INT((H30 - DATE(YEAR(H30),1,1))/7))*7+IF(YEAR(H30)>YEAR(H$21),364,0) -> 406 | X30: =MIN(51,INT((I30 - DATE(YEAR(I30),1,1))/7))*7+IF(YEAR(I30)>YEAR(I$21),364,0) -> 406 | Y30: =MIN(51,INT((J30 - DATE(YEAR(J30),1,1))/7))*7+IF(YEAR(J30)>YEAR(J$21),364,0) -> 406 | Z30: =MIN(51,INT((K30 - DATE(YEAR(K30),1,1))/7))*7+IF(YEAR(K30)>YEAR(K$21),364,0) -> 406 | AA30: =MIN(51,INT((L30 - DATE(YEAR(L30),1,1))/7))*7+IF(YEAR(L30)>YEAR(L$21),364,0) -> 406 | AB30: =MIN(51,INT((M30 - DATE(YEAR(M30),1,1))/7))*7+IF(YEAR(M30)>YEAR(M$21),364,0) -> 406 | ... AD30: =MIN(51,INT((O30 - DATE(YEAR(O30),1,1))/7))*7+IF(YEAR(O30)>YEAR(O$21),364,0) -> 406
E31: FP10 | F31: =F21+364 -> 43924 | G31: =G21+364 -> 43924 | H31: =H21+364 -> 43924 | I31: =I21+364 -> 43924 | J31: =J21+364 -> 43924 | K31: =K21+364 -> 43924 | L31: =L21+364 -> 43924 | M31: =M21+364 -> 43924 | ... O31: =O21+364 -> 43924 | T31: FP10 | U31: =MIN(51,INT((F31 - DATE(YEAR(F31),1,1))/7))*7+IF(YEAR(F31)>YEAR(F$21),364,0) -> 455 | V31: =MIN(51,INT((G31 - DATE(YEAR(G31),1,1))/7))*7+IF(YEAR(G31)>YEAR(G$21),364,0) -> 455 | W31: =MIN(51,INT((H31 - DATE(YEAR(H31),1,1))/7))*7+IF(YEAR(H31)>YEAR(H$21),364,0) -> 455 | X31: =MIN(51,INT((I31 - DATE(YEAR(I31),1,1))/7))*7+IF(YEAR(I31)>YEAR(I$21),364,0) -> 455 | Y31: =MIN(51,INT((J31 - DATE(YEAR(J31),1,1))/7))*7+IF(YEAR(J31)>YEAR(J$21),364,0) -> 455 | Z31: =MIN(51,INT((K31 - DATE(YEAR(K31),1,1))/7))*7+IF(YEAR(K31)>YEAR(K$21),364,0) -> 455 | AA31: =MIN(51,INT((L31 - DATE(YEAR(L31),1,1))/7))*7+IF(YEAR(L31)>YEAR(L$21),364,0) -> 455 | AB31: =MIN(51,INT((M31 - DATE(YEAR(M31),1,1))/7))*7+IF(YEAR(M31)>YEAR(M$21),364,0) -> 455 | ... AD31: =MIN(51,INT((O31 - DATE(YEAR(O31),1,1))/7))*7+IF(YEAR(O31)>YEAR(O$21),364,0) -> 455
U32: =MIN(51,INT((F32 - DATE(YEAR(F32),1,1))/7))*7+IF(YEAR(F32)>YEAR(F$21),364,0) -> -7
E35: =E4 -> Stocashtic Feed Periods | AL35: »
E40: Static Labour Periods
G46: typ | H46: season0 | I46: season1 | J46: season2 | K46: season3 | L46: season4 | M46: season5 | N46: season6 | O46: season7 | P46: season8
E47: Seeding periods
F48: start_wet_seeding_gs1 | G48: =F102 -> 43600 | H48: =G102 -> 43589 | I48: =H102 -> 43589 | J48: =I102 -> 43589 | K48: =J102 -> 43589 | L48: =K102 -> 43606 | M48: =L102 -> 43606 | N48: =M102 -> 43606 | ... P48: =O102 -> 43606
F49: AFO version | G49: =MIN(51,INT((G48 - DATE(YEAR(G48),1,1))/7))*7+IF(YEAR(G48)>YEAR(G48),364,0) -> 133 | H49: =MIN(51,INT((H48 - DATE(YEAR(H48),1,1))/7))*7+IF(YEAR(H48)>YEAR(H48),364,0) -> 119 | I49: =MIN(51,INT((I48 - DATE(YEAR(I48),1,1))/7))*7+IF(YEAR(I48)>YEAR(I48),364,0) -> 119 | J49: =MIN(51,INT((J48 - DATE(YEAR(J48),1,1))/7))*7+IF(YEAR(J48)>YEAR(J48),364,0) -> 119 | K49: =MIN(51,INT((K48 - DATE(YEAR(K48),1,1))/7))*7+IF(YEAR(K48)>YEAR(K48),364,0) -> 119 | L49: =MIN(51,INT((L48 - DATE(YEAR(L48),1,1))/7))*7+IF(YEAR(L48)>YEAR(L48),364,0) -> 140 | M49: =MIN(51,INT((M48 - DATE(YEAR(M48),1,1))/7))*7+IF(YEAR(M48)>YEAR(M48),364,0) -> 140 | N49: =MIN(51,INT((N48 - DATE(YEAR(N48),1,1))/7))*7+IF(YEAR(N48)>YEAR(N48),364,0) -> 140 | ... P49: =MIN(51,INT((P48 - DATE(YEAR(P48),1,1))/7))*7+IF(YEAR(P48)>YEAR(P48),364,0) -> 140
F51: end_wet_seeding_gs1 | G51: =F105 -> 43621 | H51: =G105 -> 43610 | I51: =H105 -> 43610 | J51: =I105 -> 43610 | K51: =J105 -> 43610 | L51: =K105 -> 43627 | M51: =L105 -> 43627 | N51: =M105 -> 43627 | ... P51: =O105 -> 43627
F52: AFO version | G52: =MIN(51,INT((G51 - DATE(YEAR(G51),1,1))/7))*7+IF(YEAR(G51)>YEAR(G51),364,0) -> 154 | H52: =MIN(51,INT((H51 - DATE(YEAR(H51),1,1))/7))*7+IF(YEAR(H51)>YEAR(H51),364,0) -> 140 | I52: =MIN(51,INT((I51 - DATE(YEAR(I51),1,1))/7))*7+IF(YEAR(I51)>YEAR(I51),364,0) -> 140 | J52: =MIN(51,INT((J51 - DATE(YEAR(J51),1,1))/7))*7+IF(YEAR(J51)>YEAR(J51),364,0) -> 140 | K52: =MIN(51,INT((K51 - DATE(YEAR(K51),1,1))/7))*7+IF(YEAR(K51)>YEAR(K51),364,0) -> 140 | L52: =MIN(51,INT((L51 - DATE(YEAR(L51),1,1))/7))*7+IF(YEAR(L51)>YEAR(L51),364,0) -> 161 | M52: =MIN(51,INT((M51 - DATE(YEAR(M51),1,1))/7))*7+IF(YEAR(M51)>YEAR(M51),364,0) -> 161 | N52: =MIN(51,INT((N51 - DATE(YEAR(N51),1,1))/7))*7+IF(YEAR(N51)>YEAR(N51),364,0) -> 161 | ... P52: =MIN(51,INT((P51 - DATE(YEAR(P51),1,1))/7))*7+IF(YEAR(P51)>YEAR(P51),364,0) -> 161
E54: Contract seeding
F55: start_contract_seeding_gs1 | G55: 43572 | H55: 43572 | I55: 43572 | J55: 43572 | K55: 43572 | L55: 43572 | M55: 43572 | N55: 43572 | O55: 43572 | P55: 43572
F56: AFO version | G56: =MIN(51,INT((G55 - DATE(YEAR(G55),1,1))/7))*7+IF(YEAR(G55)>YEAR(G55),364,0) -> 105 | H56: =MIN(51,INT((H55 - DATE(YEAR(H55),1,1))/7))*7+IF(YEAR(H55)>YEAR(H55),364,0) -> 105 | I56: =MIN(51,INT((I55 - DATE(YEAR(I55),1,1))/7))*7+IF(YEAR(I55)>YEAR(I55),364,0) -> 105 | J56: =MIN(51,INT((J55 - DATE(YEAR(J55),1,1))/7))*7+IF(YEAR(J55)>YEAR(J55),364,0) -> 105 | K56: =MIN(51,INT((K55 - DATE(YEAR(K55),1,1))/7))*7+IF(YEAR(K55)>YEAR(K55),364,0) -> 105 | L56: =MIN(51,INT((L55 - DATE(YEAR(L55),1,1))/7))*7+IF(YEAR(L55)>YEAR(L55),364,0) -> 105 | M56: =MIN(51,INT((M55 - DATE(YEAR(M55),1,1))/7))*7+IF(YEAR(M55)>YEAR(M55),364,0) -> 105 | N56: =MIN(51,INT((N55 - DATE(YEAR(N55),1,1))/7))*7+IF(YEAR(N55)>YEAR(N55),364,0) -> 105 | ... P56: =MIN(51,INT((P55 - DATE(YEAR(P55),1,1))/7))*7+IF(YEAR(P55)>YEAR(P55),364,0) -> 105
F58: end_contract_seeding_gs1 | G58: =G51 -> 43621 | H58: =H51 -> 43610 | I58: =I51 -> 43610 | J58: =J51 -> 43610 | K58: =K51 -> 43610 | L58: =L51 -> 43627 | M58: =M51 -> 43627 | N58: =N51 -> 43627 | ... P58: =P51 -> 43627
F59: AFO version | G59: =MIN(51,INT((G58 - DATE(YEAR(G58),1,1))/7))*7+IF(YEAR(G58)>YEAR(G58),364,0) -> 154 | H59: =MIN(51,INT((H58 - DATE(YEAR(H58),1,1))/7))*7+IF(YEAR(H58)>YEAR(H58),364,0) -> 140 | I59: =MIN(51,INT((I58 - DATE(YEAR(I58),1,1))/7))*7+IF(YEAR(I58)>YEAR(I58),364,0) -> 140 | J59: =MIN(51,INT((J58 - DATE(YEAR(J58),1,1))/7))*7+IF(YEAR(J58)>YEAR(J58),364,0) -> 140 | K59: =MIN(51,INT((K58 - DATE(YEAR(K58),1,1))/7))*7+IF(YEAR(K58)>YEAR(K58),364,0) -> 140 | L59: =MIN(51,INT((L58 - DATE(YEAR(L58),1,1))/7))*7+IF(YEAR(L58)>YEAR(L58),364,0) -> 161 | M59: =MIN(51,INT((M58 - DATE(YEAR(M58),1,1))/7))*7+IF(YEAR(M58)>YEAR(M58),364,0) -> 161 | N59: =MIN(51,INT((N58 - DATE(YEAR(N58),1,1))/7))*7+IF(YEAR(N58)>YEAR(N58),364,0) -> 161 | ... P59: =MIN(51,INT((P58 - DATE(YEAR(P58),1,1))/7))*7+IF(YEAR(P58)>YEAR(P58),364,0) -> 161
E61: Harvest periods
F62: harv_date | G62: =MIN(Crop!I99:I117) -> 43784 | H62: =MIN(Crop!J99:J117) -> 43784 | I62: =MIN(Crop!K99:K117) -> 43784 | J62: =MIN(Crop!L99:L117) -> 43784 | K62: =MIN(Crop!M99:M117) -> 43784 | L62: =MIN(Crop!N99:N117) -> 43784 | M62: =MIN(Crop!O99:O117) -> 43784 | N62: =MIN(Crop!P99:P117) -> 43784 | ... P62: =MIN(Crop!R99:R117) -> 43784
F63: AFO version | G63: =MIN(51,INT((G62 - DATE(YEAR(G62),1,1))/7))*7 -> 315 | H63: =MIN(51,INT((H62 - DATE(YEAR(H62),1,1))/7))*7 -> 315 | I63: =MIN(51,INT((I62 - DATE(YEAR(I62),1,1))/7))*7 -> 315 | J63: =MIN(51,INT((J62 - DATE(YEAR(J62),1,1))/7))*7 -> 315 | K63: =MIN(51,INT((K62 - DATE(YEAR(K62),1,1))/7))*7 -> 315 | L63: =MIN(51,INT((L62 - DATE(YEAR(L62),1,1))/7))*7 -> 315 | M63: =MIN(51,INT((M62 - DATE(YEAR(M62),1,1))/7))*7 -> 315 | N63: =MIN(51,INT((N62 - DATE(YEAR(N62),1,1))/7))*7 -> 315 | ... P63: =MIN(51,INT((P62 - DATE(YEAR(P62),1,1))/7))*7 -> 315
F65: harv_period_lengths | G65: 14 | H65: 14 | I65: 14 | J65: 14 | K65: 14 | L65: 14 | M65: 14 | N65: 14 | O65: 14 | P65: 14
G66: 37 | H66: 37 | I66: 37 | J66: 37 | K66: 37 | L66: 37 | M66: 37 | N66: 37 | O66: 37 | P66: 37
F67: AFO version | G67: =INT(G65/7)*7 -> 14 | H67: =INT(H65/7)*7 -> 14 | I67: =INT(I65/7)*7 -> 14 | J67: =INT(J65/7)*7 -> 14 | K67: =INT(K65/7)*7 -> 14 | L67: =INT(L65/7)*7 -> 14 | M67: =INT(M65/7)*7 -> 14 | N67: =INT(N65/7)*7 -> 14 | ... P67: =INT(P65/7)*7 -> 14
G68: =INT(G66/7)*7 -> 35 | H68: =INT(H66/7)*7 -> 35 | I68: =INT(I66/7)*7 -> 35 | J68: =INT(J66/7)*7 -> 35 | K68: =INT(K66/7)*7 -> 35 | L68: =INT(L66/7)*7 -> 35 | M68: =INT(M66/7)*7 -> 35 | N68: =INT(N66/7)*7 -> 35 | ... P68: =INT(P66/7)*7 -> 35
E72: =E40 -> Static Labour Periods | AL72: »
E77: Stocashtic Labour Periods
G98: early | K98: medium | M98: late | U98: Day of yr - input for AFO
F100: typ | G100: season0 | H100: season1 | I100: season2 | J100: season3 | K100: season4 | L100: season5 | M100: season6 | N100: season7 | O100: season8 | U100: =F100 -> typ | V100: =G100 -> season0 | W100: =H100 -> season1 | X100: =I100 -> season2 | Y100: =J100 -> season3 | Z100: =K100 -> season4 | AA100: =L100 -> season5 | AB100: =M100 -> season6 | ... AD100: =O100 -> season8
E101: P00 | F101: =F21 -> 43560 | G101: =G21 -> 43560 | H101: =H21 -> 43560 | I101: =I21 -> 43560 | J101: =J21 -> 43560 | K101: =K21 -> 43560 | L101: =L21 -> 43560 | M101: =M21 -> 43560 | ... O101: =O21 -> 43560 | P101: start of year | T101: P00 | U101: =MIN(51,INT((F101 - DATE(YEAR(F101),1,1))/7))*7+IF(YEAR(F101)>YEAR(F$101),364,0) -> 91 | V101: =MIN(51,INT((G101 - DATE(YEAR(G101),1,1))/7))*7+IF(YEAR(G101)>YEAR(G$101),364,0) -> 91 | W101: =MIN(51,INT((H101 - DATE(YEAR(H101),1,1))/7))*7+IF(YEAR(H101)>YEAR(H$101),364,0) -> 91 | X101: =MIN(51,INT((I101 - DATE(YEAR(I101),1,1))/7))*7+IF(YEAR(I101)>YEAR(I$101),364,0) -> 91 | Y101: =MIN(51,INT((J101 - DATE(YEAR(J101),1,1))/7))*7+IF(YEAR(J101)>YEAR(J$101),364,0) -> 91 | Z101: =MIN(51,INT((K101 - DATE(YEAR(K101),1,1))/7))*7+IF(YEAR(K101)>YEAR(K$101),364,0) -> 91 | AA101: =MIN(51,INT((L101 - DATE(YEAR(L101),1,1))/7))*7+IF(YEAR(L101)>YEAR(L$101),364,0) -> 91 | AB101: =MIN(51,INT((M101 - DATE(YEAR(M101),1,1))/7))*7+IF(YEAR(M101)>YEAR(M$101),364,0) -> 91 | ... AD101: =MIN(51,INT((O101 - DATE(YEAR(O101),1,1))/7))*7+IF(YEAR(O101)>YEAR(O$101),364,0) -> 91
...

Sheet Saltbush
C4: « | D4: 661.25
D5: 661.25 | E5: Däta | G5: AREA OF SALTBUSH
G7: 39336.602
C8: 0
G15: Proportion of understorey | J15: 0.9
G16: Saltbush stems/ha | J16: 660
G17: Landuse | J17: sp
G19: =G5 -> AREA OF SALTBUSH | X19: »
C23: « | D23: 417.58461
D24: 417.58461 | E24: Däta | G24: COST OF ESTABLISHING SALTBUSH
G26: 44719.602
C27: 0
J31: Saltbush | K31: Understory
G34: Cost of establishment | I34: /ha | J34: 453.5 | K34: 80
G35: Probability of success | J35: 0.8 | K35: 0.8
G36: Productive Life of stand | I36: yrs | J36: 20 | K36: 10
G37: Expected estab date | J37: 43466 | K37: =MIN(364,INT((J37 - DATE(YEAR(J37),1,1)))) -> 0
I39: PMT | J39: =PMT(5%,i_saltbush_life,-i_saltbush_estab_cost/i_saltbush_success) -> 45.487517 | K39: =PMT(5%,i_understory_life,-i_understory_estab_cost/i_understory_success) -> 12.950457
G41: =G24 -> COST OF ESTABLISHING SALTBUSH | X41: »
C45: « | D45: 4408.925
D46: 4408.925 | E46: Däta | G46: SALTBUSH PRODUCTIVITY & FEED VALUE & SELECTIVITY
G48: 38530.673 | J48: *Jun22: z axis still needs to be calibrated
C49: 0
J50: Growth
K51: Loss in prodn of saltbush
I52: Typical FOO | J52: Typical growth rate | K52: when ungrazed | M52: DM total ash | P52: Diet selection | R52: Expected propn | T52: Crude
I53: g/stem | J53: g/stem/day | K53: %/day | M53: % | N53: SB OMD% | P53: Ratio SB vol / Total vol | R53: SLP in diet | T53: Protein
G56: Typ | H56: P0 | I56: 50 | J56: 4.5 | K56: 0.01 | M56: 0.237 | N56: 0.64 | P56: 0.42 | R56: 1 | T56: =MAX(12%,MIN(20%,20%-(P56-30%)*0.8)) -> 0.12
H57: P1 | I57: 100 | J57: 2.2 | K57: 0.01 | M57: 0.237 | P57: 0.42 | R57: 1 | T57: =MAX(12%,MIN(20%,20%-(P57-30%)*0.8)) -> 0.12
H58: P2 | I58: 100 | J58: 2.2 | K58: 0.01 | M58: 0.237 | P58: 0.32 | R58: 1 | T58: =MAX(12%,MIN(20%,20%-(P58-30%)*0.8)) -> 0.184
H59: P3 | I59: 150 | J59: 1.8 | K59: 0.01 | M59: 0.237 | P59: 0.14 | R59: 1 | T59: =MAX(12%,MIN(20%,20%-(P59-30%)*0.8)) -> 0.2
H60: P4 | I60: 300 | J60: 0.75 | K60: 0.01 | M60: 0.237 | P60: 0.12 | R60: 1 | T60: =MAX(12%,MIN(20%,20%-(P60-30%)*0.8)) -> 0.2
H61: P5 | I61: 300 | J61: 0.75 | K61: 0.01 | M61: 0.237 | P61: 0.23 | R61: 1 | T61: =MAX(12%,MIN(20%,20%-(P61-30%)*0.8)) -> 0.2
H62: P6 | I62: 325 | J62: 1 | K62: 0.01 | M62: 0.237 | P62: 0.32 | R62: 1 | T62: =MAX(12%,MIN(20%,20%-(P62-30%)*0.8)) -> 0.184
H63: P7 | I63: 350 | J63: 1.5 | K63: 0.01 | M63: 0.237 | P63: 0.42 | R63: 1 | T63: =MAX(12%,MIN(20%,20%-(P63-30%)*0.8)) -> 0.12
H64: P8 | I64: 50 | J64: 4.5 | K64: 0.01 | M64: 0.237 | P64: 0.51 | R64: 1 | T64: =MAX(12%,MIN(20%,20%-(P64-30%)*0.8)) -> 0.12
H65: P9 | I65: 50 | J65: 4.5 | K65: 0.01 | M65: 0.237 | P65: 0.6 | R65: 1 | T65: =MAX(12%,MIN(20%,20%-(P65-30%)*0.8)) -> 0.12
G66: Z0 | H66: P0 | I66: 50 | J66: 4.5 | K66: 0.01 | M66: =M65 -> 0.237 | P66: 0.42 | R66: 1 | T66: =MAX(12%,MIN(20%,20%-(P66-30%)*0.8)) -> 0.12
H67: P1 | I67: 100 | J67: 2.2 | K67: 0.01 | M67: =M66 -> 0.237 | P67: 0.42 | R67: 1 | T67: =MAX(12%,MIN(20%,20%-(P67-30%)*0.8)) -> 0.12
H68: P2 | I68: 100 | J68: 2.2 | K68: 0.01 | M68: =M67 -> 0.237 | P68: 0.32 | R68: 1 | T68: =MAX(12%,MIN(20%,20%-(P68-30%)*0.8)) -> 0.184
...

Sheet Labour
E3: 10Aug21: Added a time period for txed jobs and the Seeding & harvest Prepartion and packing away 4 Aug21: Spread the fixed jobs across more dates so that it didn't cause problems in short labour periods. Probably better to be coded as a length of the task so that it is more universal.
E9: Labour Bounds
H10: note
H14: Manager | J14: Permanent | L14: Casual
G16: Min | H16: 1 | J16: 0 | L16: 0
G17: Max | H17: 1 | J17: 1 | L17: 999
G19: Min Seeding/Harv | L19: 0
G20: Max Seeding/Harv | L20: 999
E24: =E9 -> Labour Bounds | Z24: »
E29: Leave
H34: Manager | J34: Permanent | L34: Casual
G36: Sick | J36: 10
G38: Leave Length | H38: 28 | J38: 28
E41: =E29 -> Leave | Z41: »
E46: Daily hours and efficiency
H51: Manager | I51: Permanent | J51: Casual
G52: weekdays | H52: 9 | I52: 8 | J52: 8
G53: weekends | H53: 4.5 | I53: 0 | J53: 0
G54: seeding | H54: 10 | I54: 9 | J54: 8
G55: harvest | H55: 9 | I55: 9 | J55: 8
G57: Supervision required
I58: Permanent | J58: Casual
H59: normal | I59: 0.07 | J59: 0.15
H60: seedingharv | I60: 0.02 | J60: 0.1
E62: =E46 -> Daily hours and efficiency | Z62: »
E67: Fixed Labour
I68: Note
F71: Tax | J71: Planning | N71: BAS | R71: Super & WC | V71: Learn
F72: date | G72: days | H72: hours | J72: date | K72: days | L72: hours | N72: date | O72: days | P72: hours | R72: date | S72: days | T72: hours | V72: hours
E73: 43525 | F73: =MIN(364,INT((E73 - DATE(YEAR(E73),1,1)))) -> 59 | G73: 15 | H73: 6 | I73: 43466 | J73: =MIN(364,INT((I73 - DATE(YEAR(I73),1,1)))) -> 0 | K73: 10 | L73: 4 | M73: 43497 | N73: =MIN(364,INT((M73 - DATE(YEAR(M73),1,1)))) -> 31 | O73: 21 | P73: 20 | Q73: 43525 | R73: =MIN(364,INT((Q73 - DATE(YEAR(Q73),1,1)))) -> 59 | S73: 21 | T73: 10 | V73: 66
E74: 43556 | F74: =MIN(364,INT((E74 - DATE(YEAR(E74),1,1)))) -> 90 | G74: 30 | H74: 10 | I74: 43497 | J74: =MIN(364,INT((I74 - DATE(YEAR(I74),1,1)))) -> 31 | K74: 10 | L74: 4 | M74: 43556 | N74: =MIN(364,INT((M74 - DATE(YEAR(M74),1,1)))) -> 90 | O74: 21 | P74: 20 | Q74: 43631 | R74: =MIN(364,INT((Q74 - DATE(YEAR(Q74),1,1)))) -> 165 | S74: 21 | T74: 10
E75: 43631 | F75: =MIN(364,INT((E75 - DATE(YEAR(E75),1,1)))) -> 165 | G75: 15 | H75: 5 | I75: 43525 | J75: =MIN(364,INT((I75 - DATE(YEAR(I75),1,1)))) -> 59 | K75: 10 | L75: 4 | M75: 43647 | N75: =MIN(364,INT((M75 - DATE(YEAR(M75),1,1)))) -> 181 | O75: 21 | P75: 20 | Q75: 43709 | R75: =MIN(364,INT((Q75 - DATE(YEAR(Q75),1,1)))) -> 243 | S75: 21 | T75: 10
I76: 43556 | J76: =MIN(364,INT((I76 - DATE(YEAR(I76),1,1)))) -> 90 | K76: 10 | L76: 4 | M76: 43739 | N76: =MIN(364,INT((M76 - DATE(YEAR(M76),1,1)))) -> 273 | O76: 21 | P76: 20 | Q76: 43814 | R76: =MIN(364,INT((Q76 - DATE(YEAR(Q76),1,1)))) -> 348 | S76: 21 | T76: 10
I77: 43586 | J77: =MIN(364,INT((I77 - DATE(YEAR(I77),1,1)))) -> 120 | K77: 10 | L77: 4
I78: 43631 | J78: =MIN(364,INT((I78 - DATE(YEAR(I78),1,1)))) -> 165 | K78: 10 | L78: 4
I79: 43647 | J79: =MIN(364,INT((I79 - DATE(YEAR(I79),1,1)))) -> 181 | K79: 10 | L79: 4
I80: 43678 | J80: =MIN(364,INT((I80 - DATE(YEAR(I80),1,1)))) -> 212 | K80: 10 | L80: 4
I81: 43709 | J81: =MIN(364,INT((I81 - DATE(YEAR(I81),1,1)))) -> 243 | K81: 10 | L81: 4
I82: 43739 | J82: =MIN(364,INT((I82 - DATE(YEAR(I82),1,1)))) -> 273 | K82: 10 | L82: 4
I83: 43770 | J83: =MIN(364,INT((I83 - DATE(YEAR(I83),1,1)))) -> 304 | K83: 10 | L83: 4
...

Sheet Annual
C4: « | AD4: ïnsertcolumnstart
D5: 0 | E5: Däta | G5: Data Sharing for Annual Pasture sheet (P1a)
G6: Standard format for all data transferred between modules
G7: 37998.514 | H7: 37998.514
C8: 1
C13: FïlterStart | J13: frëeze
G16: Relative Intake Coefficients | K16: =J75 -> typ | L16: =K75 -> z0 | M16: =L75 -> z1 | N16: =M75 -> z2 | O16: =N75 -> z3 | P16: =O75 -> z4 | Q16: =P75 -> z5 | R16: =Q75 -> z6 | ... T16: =S75 -> z8
H17: Proportion of clover in the sward | K17: 0.2 | L17: 0.2 | M17: 0.2 | N17: 0.2 | O17: 0.2 | P17: 0.2 | Q17: 0.2 | R17: 0.2 | S17: 0.2 | T17: 0.2
H18: Height ratio scalar | K18: 2 | L18: 2 | M18: 2 | N18: 2 | O18: 2 | P18: 2 | Q18: 2 | R18: 2 | S18: 2 | T18: 2
H20: Length of establishment phase (days) | K20: 30 | L20: =K20 -> 30 | M20: =L20 -> 30 | N20: =M20 -> 30 | O20: =N20 -> 30 | P20: =O20 -> 30 | Q20: =P20 -> 30 | R20: =Q20 -> 30 | S20: =R20 -> 30 | T20: =S20 -> 30
H21: Break of season (doy) | K21: {=TRANSPOSE(General!i_break)} -> 133 | L21: 119 | M21: 119 | N21: 119 | O21: 119 | P21: 140 | Q21: 140 | R21: 140 | S21: 140 | T21: 140
H23: Note: The calculation in the tble below could be done in the pre-calcs and then the input above could be defined as a sensitivity variable.
H24: Pasture stage | J24: FP0 | K24: =MIN(1,(MAX(0, Periods!U22-(K$21+K$20))+MAX(0,K$21-Periods!U21))/(Periods!U22-Periods!U21)) -> 1 | L24: =MIN(1,(MAX(0, Periods!V22-(L$21+L$20))+MAX(0,L$21-Periods!V21))/(Periods!V22-Periods!V21)) -> 1 | M24: =MIN(1,(MAX(0, Periods!W22-(M$21+M$20))+MAX(0,M$21-Periods!W21))/(Periods!W22-Periods!W21)) -> 1 | N24: =MIN(1,(MAX(0, Periods!X22-(N$21+N$20))+MAX(0,N$21-Periods!X21))/(Periods!X22-Periods!X21)) -> 1 | O24: =MIN(1,(MAX(0, Periods!Y22-(O$21+O$20))+MAX(0,O$21-Periods!Y21))/(Periods!Y22-Periods!Y21)) -> 1 | P24: =MIN(1,(MAX(0, Periods!Z22-(P$21+P$20))+MAX(0,P$21-Periods!Z21))/(Periods!Z22-Periods!Z21)) -> 1 | Q24: =MIN(1,(MAX(0, Periods!AA22-(Q$21+Q$20))+MAX(0,Q$21-Periods!AA21))/(Periods!AA22-Periods!AA21)) -> 1 | R24: =MIN(1,(MAX(0, Periods!AB22-(R$21+R$20))+MAX(0,R$21-Periods!AB21))/(Periods!AB22-Periods!AB21)) -> 1 | ... T24: =MIN(1,(MAX(0, Periods!AD22-(T$21+T$20))+MAX(0,T$21-Periods!AD21))/(Periods!AD22-Periods!AD21)) -> 1
J25: FP1 | K25: =MIN(1,(MAX(0, Periods!U23-(K$21+K$20))+MAX(0,K$21-Periods!U22))/(Periods!U23-Periods!U22)) -> 0 | L25: =MIN(1,(MAX(0, Periods!V23-(L$21+L$20))+MAX(0,L$21-Periods!V22))/(Periods!V23-Periods!V22)) -> 0.28571429 | M25: =MIN(1,(MAX(0, Periods!W23-(M$21+M$20))+MAX(0,M$21-Periods!W22))/(Periods!W23-Periods!W22)) -> 0.28571429 | N25: =MIN(1,(MAX(0, Periods!X23-(N$21+N$20))+MAX(0,N$21-Periods!X22))/(Periods!X23-Periods!X22)) -> 0.28571429 | O25: =MIN(1,(MAX(0, Periods!Y23-(O$21+O$20))+MAX(0,O$21-Periods!Y22))/(Periods!Y23-Periods!Y22)) -> 0.28571429 | P25: =MIN(1,(MAX(0, Periods!Z23-(P$21+P$20))+MAX(0,P$21-Periods!Z22))/(Periods!Z23-Periods!Z22)) -> 0 | Q25: =MIN(1,(MAX(0, Periods!AA23-(Q$21+Q$20))+MAX(0,Q$21-Periods!AA22))/(Periods!AA23-Periods!AA22)) -> 0 | R25: =MIN(1,(MAX(0, Periods!AB23-(R$21+R$20))+MAX(0,R$21-Periods!AB22))/(Periods!AB23-Periods!AB22)) -> 0 | ... T25: =MIN(1,(MAX(0, Periods!AD23-(T$21+T$20))+MAX(0,T$21-Periods!AD22))/(Periods!AD23-Periods!AD22)) -> 0
J26: FP2 | K26: =MIN(1,(MAX(0, Periods!U24-(K$21+K$20))+MAX(0,K$21-Periods!U23))/(Periods!U24-Periods!U23)) -> 0.96428571 | L26: =MIN(1,(MAX(0, Periods!V24-(L$21+L$20))+MAX(0,L$21-Periods!V23))/(Periods!V24-Periods!V23)) -> 1 | M26: =MIN(1,(MAX(0, Periods!W24-(M$21+M$20))+MAX(0,M$21-Periods!W23))/(Periods!W24-Periods!W23)) -> 1 | N26: =MIN(1,(MAX(0, Periods!X24-(N$21+N$20))+MAX(0,N$21-Periods!X23))/(Periods!X24-Periods!X23)) -> 1 | O26: =MIN(1,(MAX(0, Periods!Y24-(O$21+O$20))+MAX(0,O$21-Periods!Y23))/(Periods!Y24-Periods!Y23)) -> 1 | P26: =MIN(1,(MAX(0, Periods!Z24-(P$21+P$20))+MAX(0,P$21-Periods!Z23))/(Periods!Z24-Periods!Z23)) -> 0.83928571 | Q26: =MIN(1,(MAX(0, Periods!AA24-(Q$21+Q$20))+MAX(0,Q$21-Periods!AA23))/(Periods!AA24-Periods!AA23)) -> 0.83928571 | R26: =MIN(1,(MAX(0, Periods!AB24-(R$21+R$20))+MAX(0,R$21-Periods!AB23))/(Periods!AB24-Periods!AB23)) -> 0.83928571 | ... T26: =MIN(1,(MAX(0, Periods!AD24-(T$21+T$20))+MAX(0,T$21-Periods!AD23))/(Periods!AD24-Periods!AD23)) -> 0.83928571
J27: FP3 | K27: =MIN(1,(MAX(0, Periods!U25-(K$21+K$20))+MAX(0,K$21-Periods!U24))/(Periods!U25-Periods!U24)) -> 1 | L27: =MIN(1,(MAX(0, Periods!V25-(L$21+L$20))+MAX(0,L$21-Periods!V24))/(Periods!V25-Periods!V24)) -> 1 | M27: =MIN(1,(MAX(0, Periods!W25-(M$21+M$20))+MAX(0,M$21-Periods!W24))/(Periods!W25-Periods!W24)) -> 1 | N27: =MIN(1,(MAX(0, Periods!X25-(N$21+N$20))+MAX(0,N$21-Periods!X24))/(Periods!X25-Periods!X24)) -> 1 | O27: =MIN(1,(MAX(0, Periods!Y25-(O$21+O$20))+MAX(0,O$21-Periods!Y24))/(Periods!Y25-Periods!Y24)) -> 1 | P27: =MIN(1,(MAX(0, Periods!Z25-(P$21+P$20))+MAX(0,P$21-Periods!Z24))/(Periods!Z25-Periods!Z24)) -> 1 | Q27: =MIN(1,(MAX(0, Periods!AA25-(Q$21+Q$20))+MAX(0,Q$21-Periods!AA24))/(Periods!AA25-Periods!AA24)) -> 1 | R27: =MIN(1,(MAX(0, Periods!AB25-(R$21+R$20))+MAX(0,R$21-Periods!AB24))/(Periods!AB25-Periods!AB24)) -> 1 | ... T27: =MIN(1,(MAX(0, Periods!AD25-(T$21+T$20))+MAX(0,T$21-Periods!AD24))/(Periods!AD25-Periods!AD24)) -> 1
J28: FP4 | K28: =MIN(1,(MAX(0, Periods!U26-(K$21+K$20))+MAX(0,K$21-Periods!U25))/(Periods!U26-Periods!U25)) -> 1 | L28: =MIN(1,(MAX(0, Periods!V26-(L$21+L$20))+MAX(0,L$21-Periods!V25))/(Periods!V26-Periods!V25)) -> 1 | M28: =MIN(1,(MAX(0, Periods!W26-(M$21+M$20))+MAX(0,M$21-Periods!W25))/(Periods!W26-Periods!W25)) -> 1 | N28: =MIN(1,(MAX(0, Periods!X26-(N$21+N$20))+MAX(0,N$21-Periods!X25))/(Periods!X26-Periods!X25)) -> 1 | O28: =MIN(1,(MAX(0, Periods!Y26-(O$21+O$20))+MAX(0,O$21-Periods!Y25))/(Periods!Y26-Periods!Y25)) -> 1 | P28: =MIN(1,(MAX(0, Periods!Z26-(P$21+P$20))+MAX(0,P$21-Periods!Z25))/(Periods!Z26-Periods!Z25)) -> 1 | Q28: =MIN(1,(MAX(0, Periods!AA26-(Q$21+Q$20))+MAX(0,Q$21-Periods!AA25))/(Periods!AA26-Periods!AA25)) -> 1 | R28: =MIN(1,(MAX(0, Periods!AB26-(R$21+R$20))+MAX(0,R$21-Periods!AB25))/(Periods!AB26-Periods!AB25)) -> 1 | ... T28: =MIN(1,(MAX(0, Periods!AD26-(T$21+T$20))+MAX(0,T$21-Periods!AD25))/(Periods!AD26-Periods!AD25)) -> 1
J29: FP5 | K29: =MIN(1,(MAX(0, Periods!U27-(K$21+K$20))+MAX(0,K$21-Periods!U26))/(Periods!U27-Periods!U26)) -> 1 | L29: =MIN(1,(MAX(0, Periods!V27-(L$21+L$20))+MAX(0,L$21-Periods!V26))/(Periods!V27-Periods!V26)) -> 1 | M29: =MIN(1,(MAX(0, Periods!W27-(M$21+M$20))+MAX(0,M$21-Periods!W26))/(Periods!W27-Periods!W26)) -> 1 | N29: =MIN(1,(MAX(0, Periods!X27-(N$21+N$20))+MAX(0,N$21-Periods!X26))/(Periods!X27-Periods!X26)) -> 1 | O29: =MIN(1,(MAX(0, Periods!Y27-(O$21+O$20))+MAX(0,O$21-Periods!Y26))/(Periods!Y27-Periods!Y26)) -> 1 | P29: =MIN(1,(MAX(0, Periods!Z27-(P$21+P$20))+MAX(0,P$21-Periods!Z26))/(Periods!Z27-Periods!Z26)) -> 1 | Q29: =MIN(1,(MAX(0, Periods!AA27-(Q$21+Q$20))+MAX(0,Q$21-Periods!AA26))/(Periods!AA27-Periods!AA26)) -> 1 | R29: =MIN(1,(MAX(0, Periods!AB27-(R$21+R$20))+MAX(0,R$21-Periods!AB26))/(Periods!AB27-Periods!AB26)) -> 1 | ... T29: =MIN(1,(MAX(0, Periods!AD27-(T$21+T$20))+MAX(0,T$21-Periods!AD26))/(Periods!AD27-Periods!AD26)) -> 1
J30: FP6 | K30: =MIN(1,(MAX(0, Periods!U28-(K$21+K$20))+MAX(0,K$21-Periods!U27))/(Periods!U28-Periods!U27)) -> 1 | L30: =MIN(1,(MAX(0, Periods!V28-(L$21+L$20))+MAX(0,L$21-Periods!V27))/(Periods!V28-Periods!V27)) -> 1 | M30: =MIN(1,(MAX(0, Periods!W28-(M$21+M$20))+MAX(0,M$21-Periods!W27))/(Periods!W28-Periods!W27)) -> 1 | N30: =MIN(1,(MAX(0, Periods!X28-(N$21+N$20))+MAX(0,N$21-Periods!X27))/(Periods!X28-Periods!X27)) -> 1 | O30: =MIN(1,(MAX(0, Periods!Y28-(O$21+O$20))+MAX(0,O$21-Periods!Y27))/(Periods!Y28-Periods!Y27)) -> 1 | P30: =MIN(1,(MAX(0, Periods!Z28-(P$21+P$20))+MAX(0,P$21-Periods!Z27))/(Periods!Z28-Periods!Z27)) -> 1 | Q30: =MIN(1,(MAX(0, Periods!AA28-(Q$21+Q$20))+MAX(0,Q$21-Periods!AA27))/(Periods!AA28-Periods!AA27)) -> 1 | R30: =MIN(1,(MAX(0, Periods!AB28-(R$21+R$20))+MAX(0,R$21-Periods!AB27))/(Periods!AB28-Periods!AB27)) -> 1 | ... T30: =MIN(1,(MAX(0, Periods!AD28-(T$21+T$20))+MAX(0,T$21-Periods!AD27))/(Periods!AD28-Periods!AD27)) -> 1
J31: FP7 | K31: =MIN(1,(MAX(0, Periods!U29-(K$21+K$20))+MAX(0,K$21-Periods!U28))/(Periods!U29-Periods!U28)) -> 1 | L31: =MIN(1,(MAX(0, Periods!V29-(L$21+L$20))+MAX(0,L$21-Periods!V28))/(Periods!V29-Periods!V28)) -> 1 | M31: =MIN(1,(MAX(0, Periods!W29-(M$21+M$20))+MAX(0,M$21-Periods!W28))/(Periods!W29-Periods!W28)) -> 1 | N31: =MIN(1,(MAX(0, Periods!X29-(N$21+N$20))+MAX(0,N$21-Periods!X28))/(Periods!X29-Periods!X28)) -> 1 | O31: =MIN(1,(MAX(0, Periods!Y29-(O$21+O$20))+MAX(0,O$21-Periods!Y28))/(Periods!Y29-Periods!Y28)) -> 1 | P31: =MIN(1,(MAX(0, Periods!Z29-(P$21+P$20))+MAX(0,P$21-Periods!Z28))/(Periods!Z29-Periods!Z28)) -> 1 | Q31: =MIN(1,(MAX(0, Periods!AA29-(Q$21+Q$20))+MAX(0,Q$21-Periods!AA28))/(Periods!AA29-Periods!AA28)) -> 1 | R31: =MIN(1,(MAX(0, Periods!AB29-(R$21+R$20))+MAX(0,R$21-Periods!AB28))/(Periods!AB29-Periods!AB28)) -> 1 | ... T31: =MIN(1,(MAX(0, Periods!AD29-(T$21+T$20))+MAX(0,T$21-Periods!AD28))/(Periods!AD29-Periods!AD28)) -> 1
J32: FP8 | K32: =MIN(1,(MAX(0, Periods!U30-(K$21+K$20))+MAX(0,K$21-Periods!U29))/(Periods!U30-Periods!U29)) -> 1 | L32: =MIN(1,(MAX(0, Periods!V30-(L$21+L$20))+MAX(0,L$21-Periods!V29))/(Periods!V30-Periods!V29)) -> 1 | M32: =MIN(1,(MAX(0, Periods!W30-(M$21+M$20))+MAX(0,M$21-Periods!W29))/(Periods!W30-Periods!W29)) -> 1 | N32: =MIN(1,(MAX(0, Periods!X30-(N$21+N$20))+MAX(0,N$21-Periods!X29))/(Periods!X30-Periods!X29)) -> 1 | O32: =MIN(1,(MAX(0, Periods!Y30-(O$21+O$20))+MAX(0,O$21-Periods!Y29))/(Periods!Y30-Periods!Y29)) -> 1 | P32: =MIN(1,(MAX(0, Periods!Z30-(P$21+P$20))+MAX(0,P$21-Periods!Z29))/(Periods!Z30-Periods!Z29)) -> 1 | Q32: =MIN(1,(MAX(0, Periods!AA30-(Q$21+Q$20))+MAX(0,Q$21-Periods!AA29))/(Periods!AA30-Periods!AA29)) -> 1 | R32: =MIN(1,(MAX(0, Periods!AB30-(R$21+R$20))+MAX(0,R$21-Periods!AB29))/(Periods!AB30-Periods!AB29)) -> 1 | ... T32: =MIN(1,(MAX(0, Periods!AD30-(T$21+T$20))+MAX(0,T$21-Periods!AD29))/(Periods!AD30-Periods!AD29)) -> 1
J33: FP9 | K33: =MIN(1,(MAX(0, Periods!U31-(K$21+K$20))+MAX(0,K$21-Periods!U30))/(Periods!U31-Periods!U30)) -> 1 | L33: =MIN(1,(MAX(0, Periods!V31-(L$21+L$20))+MAX(0,L$21-Periods!V30))/(Periods!V31-Periods!V30)) -> 1 | M33: =MIN(1,(MAX(0, Periods!W31-(M$21+M$20))+MAX(0,M$21-Periods!W30))/(Periods!W31-Periods!W30)) -> 1 | N33: =MIN(1,(MAX(0, Periods!X31-(N$21+N$20))+MAX(0,N$21-Periods!X30))/(Periods!X31-Periods!X30)) -> 1 | O33: =MIN(1,(MAX(0, Periods!Y31-(O$21+O$20))+MAX(0,O$21-Periods!Y30))/(Periods!Y31-Periods!Y30)) -> 1 | P33: =MIN(1,(MAX(0, Periods!Z31-(P$21+P$20))+MAX(0,P$21-Periods!Z30))/(Periods!Z31-Periods!Z30)) -> 1 | Q33: =MIN(1,(MAX(0, Periods!AA31-(Q$21+Q$20))+MAX(0,Q$21-Periods!AA30))/(Periods!AA31-Periods!AA30)) -> 1 | R33: =MIN(1,(MAX(0, Periods!AB31-(R$21+R$20))+MAX(0,R$21-Periods!AB30))/(Periods!AB31-Periods!AB30)) -> 1 | ... T33: =MIN(1,(MAX(0, Periods!AD31-(T$21+T$20))+MAX(0,T$21-Periods!AD30))/(Periods!AD31-Periods!AD30)) -> 1
C34: ïnsertline
G35: Data Sharing for Annual Pasture sheet (P1a) | AD35: ïnsertcolumnfinish | AE35: «»
C40: « | AD40: ïnsertcolumnstart
D41: 0 | E41: Däta | G41: ABOUT Annual Pasture structure & data (P1a)
G42: Background details
G43: 37998.527 | H43: 37998.527
C44: 1
C49: FïlterStart | J49: frëeze
H51: This sheet contains pasture production, quality and rates of decline. Pasture growth rates were calculated from results
H52: of the GrassGro model run by Paul Sanford.
H53: Note: FOO is entered in the units as measured in the locality. It is later converted to the units required for the prediction of intake that is used in the Sheep Generator.
H55: Key people for EWW data: | K55: Michael Young
H56: Data sources: | K56: AusFarm model
H57: Module version | K57: P1-1a
H58: Last major review of this sheet: | K58: 45292
H60: Recent changes
C62: ïnsertline
G63: ABOUT Annual Pasture structure & data (P1a) | AD63: ïnsertcolumnfinish | AE63: «»
...

Sheet Understory
C4: « | AD4: ïnsertcolumnstart
D5: 0 | E5: Däta | G5: Data Sharing for Annual Pasture sheet (P1a)
G6: Standard format for all data transferred between modules
G7: 37998.514 | H7: 37998.514
C8: 1
C13: FïlterStart | J13: frëeze
G16: Relative Intake Coefficients | K16: =J71 -> typ | L16: =K71 -> z0 | M16: =L71 -> z1 | N16: =M71 -> z2 | O16: =N71 -> z3 | P16: =O71 -> z4 | Q16: =P71 -> z5 | R16: =Q71 -> z6 | ... T16: =S71 -> z8
H17: Proportion of clover in the sward | K17: 0.2 | L17: 0.2 | M17: 0.2 | N17: 0.2 | O17: 0.2 | P17: 0.2 | Q17: 0.2 | R17: 0.2 | S17: 0.2 | T17: 0.2
H18: Height ratio scalar | K18: 2 | L18: 2 | M18: 2 | N18: 2 | O18: 2 | P18: 2 | Q18: 2 | R18: 2 | S18: 2 | T18: 2
H20: Pasture stage | J20: FP0 | K20: =Annual!K24 -> 1 | L20: =Annual!L24 -> 1 | M20: =Annual!M24 -> 1 | N20: =Annual!N24 -> 1 | O20: =Annual!O24 -> 1 | P20: =Annual!P24 -> 1 | Q20: =Annual!Q24 -> 1 | R20: =Annual!R24 -> 1 | ... T20: =Annual!T24 -> 1
J21: FP1 | K21: =Annual!K25 -> 0 | L21: =Annual!L25 -> 0.28571429 | M21: =Annual!M25 -> 0.28571429 | N21: =Annual!N25 -> 0.28571429 | O21: =Annual!O25 -> 0.28571429 | P21: =Annual!P25 -> 0 | Q21: =Annual!Q25 -> 0 | R21: =Annual!R25 -> 0 | ... T21: =Annual!T25 -> 0
J22: FP2 | K22: =Annual!K26 -> 0.96428571 | L22: =Annual!L26 -> 1 | M22: =Annual!M26 -> 1 | N22: =Annual!N26 -> 1 | O22: =Annual!O26 -> 1 | P22: =Annual!P26 -> 0.83928571 | Q22: =Annual!Q26 -> 0.83928571 | R22: =Annual!R26 -> 0.83928571 | ... T22: =Annual!T26 -> 0.83928571
J23: FP3 | K23: =Annual!K27 -> 1 | L23: =Annual!L27 -> 1 | M23: =Annual!M27 -> 1 | N23: =Annual!N27 -> 1 | O23: =Annual!O27 -> 1 | P23: =Annual!P27 -> 1 | Q23: =Annual!Q27 -> 1 | R23: =Annual!R27 -> 1 | ... T23: =Annual!T27 -> 1
J24: FP4 | K24: =Annual!K28 -> 1 | L24: =Annual!L28 -> 1 | M24: =Annual!M28 -> 1 | N24: =Annual!N28 -> 1 | O24: =Annual!O28 -> 1 | P24: =Annual!P28 -> 1 | Q24: =Annual!Q28 -> 1 | R24: =Annual!R28 -> 1 | ... T24: =Annual!T28 -> 1
J25: FP5 | K25: =Annual!K29 -> 1 | L25: =Annual!L29 -> 1 | M25: =Annual!M29 -> 1 | N25: =Annual!N29 -> 1 | O25: =Annual!O29 -> 1 | P25: =Annual!P29 -> 1 | Q25: =Annual!Q29 -> 1 | R25: =Annual!R29 -> 1 | ... T25: =Annual!T29 -> 1
J26: FP6 | K26: =Annual!K30 -> 1 | L26: =Annual!L30 -> 1 | M26: =Annual!M30 -> 1 | N26: =Annual!N30 -> 1 | O26: =Annual!O30 -> 1 | P26: =Annual!P30 -> 1 | Q26: =Annual!Q30 -> 1 | R26: =Annual!R30 -> 1 | ... T26: =Annual!T30 -> 1
J27: FP7 | K27: =Annual!K31 -> 1 | L27: =Annual!L31 -> 1 | M27: =Annual!M31 -> 1 | N27: =Annual!N31 -> 1 | O27: =Annual!O31 -> 1 | P27: =Annual!P31 -> 1 | Q27: =Annual!Q31 -> 1 | R27: =Annual!R31 -> 1 | ... T27: =Annual!T31 -> 1
J28: FP8 | K28: =Annual!K32 -> 1 | L28: =Annual!L32 -> 1 | M28: =Annual!M32 -> 1 | N28: =Annual!N32 -> 1 | O28: =Annual!O32 -> 1 | P28: =Annual!P32 -> 1 | Q28: =Annual!Q32 -> 1 | R28: =Annual!R32 -> 1 | ... T28: =Annual!T32 -> 1
J29: FP9 | K29: =Annual!K33 -> 1 | L29: =Annual!L33 -> 1 | M29: =Annual!M33 -> 1 | N29: =Annual!N33 -> 1 | O29: =Annual!O33 -> 1 | P29: =Annual!P33 -> 1 | Q29: =Annual!Q33 -> 1 | R29: =Annual!R33 -> 1 | ... T29: =Annual!T33 -> 1
C30: ïnsertline
G31: Data Sharing for Annual Pasture sheet (P1a) | AD31: ïnsertcolumnfinish | AE31: «»
C36: « | AD36: ïnsertcolumnstart
D37: 0 | E37: Däta | G37: ABOUT Annual Pasture structure & data (P1a)
G38: Background details
G39: 37998.527 | H39: 37998.527
C40: 1
C45: FïlterStart | J45: frëeze
H47: This sheet contains pasture production, quality and rates of decline. Pasture growth rates were calculated from results
H48: of the GrassGro model run by Paul Sanford.
H49: Note: FOO is entered in the units as measured in the locality. It is later converted to the units required for the prediction of intake that is used in the Sheep Generator.
H51: Key people for CWW data: | K51: John Young, Paul Sanford
H52: Data sources: | K52: GrassGro model
H53: Module version | K53: P1-1a
H54: Last major review of this sheet: | K54: 44197
H56: Recent changes
