Workbook
Name a_c2_c0t: CropResidue!$J$271:$AM$273
Name approx_hay_yield: 'Mach General'!$B$9
Name cart_hay: Price!$B$36
Name casual_cost: Price!$B$84
Name casual_super: Price!$B$86
Name casual_workers_comp: Price!$B$88
Name clearing_value: 'Mach 1'!$A$11:$F$26
Name clearing_value: 'Mach 2'!$A$11:$F$26
Name clearing_value: 'Mach 3'!$A$11:$F$26
Name clover_propn_in_sward_stubble: CropResidue!$J$33
Name contract_bail: Price!$B$34
Name contract_harv_cost: Price!$A$8:$B$27
Name contract_harvest_rate: 'Mach General'!$A$14:$B$33
Name contract_mow_hay: Price!$B$32
Name contract_seed_cost: Price!$B$29
Name crp_insurance_date: Price!$B$46
Name diesel: Price!$B$4
Name diesel_rebate: Price!$B$6
Name equip_insurance: Finance!$B$16
Name fixed_dep: Finance!$B$13
Name flagfall: Price!$B$44
Name fuel_seeding: 'Mach 1'!$B$34
Name fuel_seeding: 'Mach 2'!$B$34
Name fuel_seeding: 'Mach 3'!$B$33
Name grain_density: 'Sup Feed'!$I$70:$AB$72
Name grain_price: Price!$L$50:$AA$70
Name grain_price_info: Price!$A$51:$J$70
Name grain_price_percentile: Price!$B$48
Name harv_fuel_consumption: 'Mach 1'!$B$75
Name harv_fuel_consumption: 'Mach 2'!$B$75
Name harv_fuel_consumption: 'Mach 3'!$B$74
Name harvest_maint: 'Mach 1'!$B$100
Name harvest_maint: 'Mach 2'!$B$100
Name harvest_maint: 'Mach 3'!$B$99
Name harvest_maint_scalar: 'Mach 1'!$A$102:$B$121
Name harvest_maint_scalar: 'Mach 2'!$A$102:$B$121
Name harvest_maint_scalar: 'Mach 3'!$A$101:$B$120
Name harvest_rate: 'Mach 1'!$A$79:$B$98
Name harvest_rate: 'Mach 2'!$A$79:$B$98
Name harvest_rate: 'Mach 3'!$A$78:$B$97
Name i_a_expo_risk_coef: General!$R$24
Name i_a_t: CropResidue!$J$322:$AM$322
Name i_agedam_propn_pos: Parameters!$L$67
Name i_agedam_propn_std_dc2: Parameters!$U$68:$AF$75
Name i_agedam_propn_y: Parameters!$AI$68:$AJ$75
Name i_agemax_s7c2: Parameters!$U$77:$AF$84
Name i_agemax_s7y: Parameters!$AI$77:$AJ$84
Name i_agemin_s7c2: Parameters!$U$85:$AF$92
Name i_agemin_s7y: Parameters!$AI$85:$AJ$92
Name i_b_t: CropResidue!$J$323:$AM$323
Name i_b0_len: Parameters!$L$713
Name i_b0_pos: Parameters!$M$713
Name i_b0_propn_b0t: CropResidue!$J$252:$AM$257
Name i_b1_pos: Parameters!$M$993
Name i_b1_propn_b1t: CropResidue!$J$240:$AM$250
Name i_biomass_scalar_ks2: CropResidue!$H$95:$J$113
Name i_bvcfw_c2: Parameters!$U$52:$AF$52
Name i_bvcfw_y: Parameters!$AI$52:$AJ$52
Name i_c_t: CropResidue!$J$324:$AM$324
Name i_c1_variation_included: General!$G$16

Sheet General
B2: «
E4: =COUNTIFS($B$1:$B4, "«")&"General model controls - Universal.xlsx" -> 1General model controls - Universal.xlsx
E5: 1 data area
B11: Ғilter
B13: 07Ғreeze
C14: ›
F16: C1 variation included | G16: FALSE
F19: Risk aversion - select the desired method from the list below.
F20: Method | G20: Risk Neutral | H20: =MATCH($G$20,$G$23:$G$27,0)-1 -> 0
F22: Methods | K22: CARA | N22: CRRA | Q22: Expo-power | T22: CVaR
F23: Risk functions hooked up in AFO | G23: Risk Neutral | K23: Pratt-Arrow absolute risk aversion coefficient | L23: 1.2e-06 | N23: Relative risk aversion coefficient | O23: 0.7 | Q23: r | R23: 0.64 | T23: Tail Alpha | U23: 0.9
G24: CARA | Q24: a | R24: -0.004612 | T24: Tail lambda | U24: 0.5
G25: CRRA
G26: Expo | P26: Initial wealth | Q26: 500000
G27: CVaR
W29: ‹›
X31: «»
C37: «
E38: Däta | G38: Fert info | I38: Enter parameters for the expected fertiliser being applied in each cetegory. This info is used to calculate application time.
I41: *info source from csbp
G43: fertiliser category | H43: price ($/t) | I43: fert_density | J43: N proportion | K43: propn of N that is urea
G44: lime | H44: =29+22 -> 51 | I44: 1.3 | J44: 0 | K44: 0
G45: super | H45: 536 | I45: 1.17 | J45: 0 | K45: 0
G46: 60map40mop | H46: 1017 | I46: =0.6*I49+0.4*I48 -> 0.998 | J46: =0.6*J49+0.4*J48 -> 0.066 | K46: 0
G47: soa | H47: =453+22 -> 475 | I47: 1.08 | J47: 0.21 | K47: 0
G48: mop | H48: =676+22 -> 698 | I48: 1.1 | J48: 0 | K48: 0
G49: map | H49: =1209+22 -> 1231 | I49: 0.93 | J49: 0.11 | K49: 0
G50: ns31 | H50: =674+22 -> 696 | I50: 0.95 | J50: 0.343 | K50: 0.6
G51: agflow | H51: =1083+22 -> 1105 | I51: 0.97 | J51: 0.276 | K51: 0
G52: urea | H52: =830+30 -> 860 | I52: 0.7 | J52: 0.46 | K52: 1
G53: flexi-n | H53: =621+22 -> 643 | I53: 1.32 | J53: 0.32 | K53: 0.35
G61: =G38 -> Fert info | W61: »
G65: Crop Landuses | I65: All landuses | K65: Fert | M65: Chem
G66: b | I66: a | K66: lime | M66: knock
G67: bd | I67: a2 | K67: early | M67: pre-em
G68: f | I68: b | K68: at_seeding | M68: selective_and_spraytop
G69: h | I69: bd | K69: mid | M69: fungicide
G70: i | I70: f | K70: late
G71: k | I71: h
G72: l | I72: i
...

Sheet Price
A3: Machinery
A4: diesel | B4: 1.8 | C4: $/l
A6: diesel_rebate | B6: 0.38 | C6: $/l
A8: Contract harvest cost | B8: price
A9: =General!G66 -> b | B9: 680 | C9: $/seperator hr
A10: =General!G67 -> bd | B10: 680 | C10: $/seperator hr
A11: =General!G68 -> f | B11: 680 | C11: $/seperator hr
A12: =General!G69 -> h | B12: 680 | C12: $/seperator hr
A13: =General!G70 -> i | B13: 680 | C13: $/seperator hr
A14: =General!G71 -> k | B14: 680 | C14: $/seperator hr
A15: =General!G72 -> l | B15: 680 | C15: $/seperator hr
A16: =General!G73 -> lf | B16: 680 | C16: $/seperator hr
A17: =General!G74 -> ms | B17: 680 | C17: $/seperator hr
A18: =General!G75 -> o | B18: 680 | C18: $/seperator hr
A19: =General!G76 -> od | B19: 680 | C19: $/seperator hr
A20: =General!G77 -> of | B20: 680 | C20: $/seperator hr
... A27: =General!G84 -> zd | B27: 680 | C27: $/seperator hr
A29: Contract seed cost | B29: 100 | C29: $/ha
A31: Hay making - mow/condition/rake, bail and cart
A32: contract mow hay | B32: 60 | C32: $/ha
A34: contract bail | B34: 35 | C34: $/t
A36: cart hay | B36: 15 | C36: $/t
A38: Sup
A39: Cartage from neighbour | B39: 15 | C39: $/t
A41: Transaction cost from neighbour | B41: 20 | C41: $/t
A43: Crop
A44: Flagfall | B44: 3.5
A46: insurance date | B46: =MIN(364,INT((C46 - DATE(YEAR(C46),1,1)))) -> 226 | C46: 43692
A48: Grain price percentile | B48: 50 | K48: Price for firsts
M49: Harvested | R49: Grazed | W49: Baled
L50: s2 | M50: Harv | N50: Harv | O50: Harv | P50: Harv | Q50: Harv | R50: Graz | S50: Graz | T50: Graz | U50: Graz | V50: Graz | W50: Bale | X50: Bale | Y50: Bale | Z50: Bale | AA50: Bale
A51: grain price | B51: is_supp | C51: is_crop | D51: seconds_discount | E51: prop_firsts | F51: prop_seconds | G51: incur_rail_cost | H51: cartage_km_cost | I51: grain_tolls | J51: insurance | L51: percentile | M51: 10 | N51: 30 | O51: 50 | P51: 70 | Q51: 90 | R51: 10 | S51: 30 | T51: 50 | U51: 70 | V51: 90 | W51: 10 | X51: 30 | Y51: 50 | Z51: 70 | AA51: 90
A52: =General!G66 -> b | B52: TRUE | C52: TRUE | D52: 0.1 | E52: 0.7 | F52: =1-E52 -> 0.3 | G52: TRUE | H52: 0.36 | I52: 14.65 | J52: 1.5 | L52: =A52 -> b | M52: 246 | N52: 282 | O52: 305 | P52: 332 | Q52: 368 | R52: 0 | S52: 0 | T52: 0 | U52: 0 | V52: 0 | W52: =Y52*0.65 -> 97.5 | X52: =Y52*0.8 -> 120 | Y52: 150 | Z52: =Y52*1.2 -> 180 | AA52: =Y52*1.35 -> 202.5
A53: =General!G67 -> bd | B53: TRUE | C53: TRUE | D53: =D52 -> 0.1 | E53: =E52 -> 0.7 | F53: =F52 -> 0.3 | G53: TRUE | H53: =H52 -> 0.36 | I53: =I52 -> 14.65 | J53: =J52 -> 1.5 | L53: =A53 -> bd | M53: =M52 -> 246 | N53: =N52 -> 282 | O53: =O52 -> 305 | P53: =P52 -> 332 | Q53: =Q52 -> 368 | R53: =R52 -> 0 | S53: =S52 -> 0 | T53: =T52 -> 0 | ... AA53: =AA52 -> 202.5
A54: =General!G68 -> f | B54: TRUE | C54: TRUE | D54: 0 | E54: 1 | F54: =1-E54 -> 0 | G54: TRUE | H54: 0.36 | I54: 17.05 | J54: 1.5 | L54: =A54 -> f | M54: =M58 -> 289 | N54: =N58 -> 329 | O54: =O58 -> 352 | P54: =P58 -> 372 | Q54: =Q58 -> 434 | R54: 0 | S54: 0 | T54: 0 | U54: 0 | V54: 0 | W54: =Y54*0.65 -> 97.5 | X54: =Y54*0.8 -> 120 | Y54: 150 | Z54: =Y54*1.2 -> 180 | AA54: =Y54*1.35 -> 202.5
A55: =General!G69 -> h | B55: TRUE | C55: TRUE | D55: 0 | E55: 1 | F55: =1-E55 -> 0 | G55: TRUE | H55: 0.5 | I55: 1.5 | J55: 1.5 | L55: =A55 -> h | M55: =M61 -> 245.65 | N55: =N61 -> 279.65 | O55: =O61 -> 299.2 | P55: =P61 -> 316.2 | Q55: =Q61 -> 368.9 | R55: 0 | S55: 0 | T55: 0 | U55: 0 | V55: 0 | W55: =Y55*0.65 -> 97.5 | X55: =Y55*0.8 -> 120 | Y55: 150 | Z55: =Y55*1.2 -> 180 | AA55: =Y55*1.35 -> 202.5
A56: =General!G70 -> i | B56: TRUE | C56: TRUE | D56: 0 | E56: 1 | F56: =1-E56 -> 0 | G56: TRUE | H56: 0.36 | I56: 14.65 | J56: 1.5 | L56: =A56 -> i | M56: =M58 -> 289 | N56: =N58 -> 329 | O56: =O58 -> 352 | P56: =P58 -> 372 | Q56: =Q58 -> 434 | R56: 0 | S56: 0 | T56: 0 | U56: 0 | V56: 0 | W56: =Y56*0.65 -> 97.5 | X56: =Y56*0.8 -> 120 | Y56: 150 | Z56: =Y56*1.2 -> 180 | AA56: =Y56*1.35 -> 202.5
A57: =General!G71 -> k | B57: TRUE | C57: TRUE | D57: 0 | E57: 1 | F57: =1-E57 -> 0 | G57: TRUE | H57: 0.36 | I57: 17.05 | J57: 1.5 | L57: =A57 -> k | M57: =M58 -> 289 | N57: =N58 -> 329 | O57: =O58 -> 352 | P57: =P58 -> 372 | Q57: =Q58 -> 434 | R57: 0 | S57: 0 | T57: 0 | U57: 0 | V57: 0 | W57: =Y57*0.65 -> 97.5 | X57: =Y57*0.8 -> 120 | Y57: 150 | Z57: =Y57*1.2 -> 180 | AA57: =Y57*1.35 -> 202.5
A58: =General!G72 -> l | B58: TRUE | C58: TRUE | D58: 0 | E58: 1 | F58: =1-E58 -> 0 | G58: TRUE | H58: 0.36 | I58: 13.15 | J58: 1.5 | L58: =A58 -> l | M58: 289 | N58: 329 | O58: 352 | P58: 372 | Q58: 434 | R58: 0 | S58: 0 | T58: 0 | U58: 0 | V58: 0 | W58: =Y58*0.65 -> 97.5 | X58: =Y58*0.8 -> 120 | Y58: 150 | Z58: =Y58*1.2 -> 180 | AA58: =Y58*1.35 -> 202.5
A59: =General!G73 -> lf | B59: TRUE | C59: TRUE | D59: 0 | E59: 1 | F59: =1-E59 -> 0 | G59: TRUE | H59: =H58 -> 0.36 | I59: =I58 -> 13.15 | J59: =J58 -> 1.5 | L59: =A59 -> lf | M59: =M58 -> 289 | N59: =N58 -> 329 | O59: =O58 -> 352 | P59: =P58 -> 372 | Q59: =Q58 -> 434 | R59: =R58 -> 0 | S59: =S58 -> 0 | T59: =T58 -> 0 | ... AA59: =AA58 -> 202.5
...

Sheet Finance
A2: Interest rates
A3: interest | B3: 0.045
A5: opportunity cost
A6: opportunity cost capital | B6: 0.045
A8: ROE
A9: min roe steady-state | B9: 0
A10: min roe stochastic | B10: 0
A12: Depreciation rates
A13: fixed dep | B13: 0.02
A15: Insurance
A16: Equipment insurance rate | B16: 0.02
A18: Working Capital Constraint
A19: Working Capital constraint included | B19: FALSE

Sheet Sup Feed
C3: «
E4: Däta | G4: LIVESTOCK FEEDS - SELECTIVITY
G5: Trail feeding information
G6: 44639
C7: 0
J9: Diet selection | L9: Diet selection
J10: Included | L10: Ratio sup vol / Total vol
J11: FALSE | L11: 0.5
G13: =G4 -> LIVESTOCK FEEDS - SELECTIVITY | AF13: »
C17: «
E18: Däta | G18: LIVESTOCK FEEDS - CONFINEMENT
G19: Confinement factors
G20: 44639
C21: 0
J22: Confinement | L22: Confinement
J23: machinery | L23: labour
J24: cost factor | L24: factor
J25: 0.5 | L25: 0.5
G27: =G18 -> LIVESTOCK FEEDS - CONFINEMENT | AF27: »
C31: «
E32: Däta | G32: LIVESTOCK FEED - Grain is a Supplementary feed
G33: Energy, Dry Matter x Feed Type
G34: 38576.729
J38: =J53 -> b | K38: =K53 -> bd | L38: =L53 -> f | M38: =M53 -> h | N38: =N53 -> i | O38: =O53 -> k | P38: =P53 -> l | Q38: =Q53 -> lf | ... AB38: =AB53 -> zd
I39: supp_inc | J39: TRUE | K39: TRUE | L39: FALSE | M39: TRUE | N39: FALSE | O39: FALSE | P39: TRUE | Q39: FALSE | R39: FALSE | S39: TRUE | T39: TRUE | U39: FALSE | V39: FALSE | W39: FALSE | X39: FALSE | Y39: TRUE | Z39: TRUE | AA39: FALSE | AB39: FALSE
G42: =G32 -> LIVESTOCK FEED - Grain is a Supplementary feed | AF42: »
C46: «
E47: Däta | G47: LIVESTOCK FEED - ENERGY, VOLUMES, EATEN
G48: Energy, Dry Matter x Feed Type
G49: 38576.729
J53: {=TRANSPOSE(General!G66:G84)} -> b | K53: bd | L53: f | M53: h | N53: i | O53: k | P53: l | Q53: lf | R53: ms | S53: o | T53: od | U53: of | V53: r | W53: rd | X53: v | Y53: w | Z53: wd | AA53: z | AB53: zd
G54: (MJ / t DM) | I54: energy | J54: 12100 | K54: 12100 | L54: 0 | M54: 7000 | N54: 0 | O54: 0 | P54: 13300 | Q54: 0 | R54: =0.65*J54+0.35*P54 -> 12520 | S54: 11400 | T54: 11400 | U54: 0 | V54: 0 | W54: 0 | X54: 0 | Y54: 12100 | Z54: 12100 | AA54: 0 | AB54: 0
G55: (%) | I55: cp | J55: 0.12 | K55: 0.12 | L55: 0.216 | M55: 0.08 | N55: 0.216 | O55: 0.216 | P55: 0.3 | Q55: 0.3 | R55: =0.65*J55+0.35*P55 -> 0.183 | S55: 0.1 | T55: 0.1 | U55: 0.1 | V55: 0.215 | W55: 0.215 | X55: 0.08 | Y55: 0.125 | Z55: 0.125 | AA55: 0.215 | AB55: 0.215
G56: (%) | I56: dry matter content | J56: 0.9 | K56: 0.9 | L56: 0.9 | M56: 0.9 | N56: 0.9 | O56: 0.9 | P56: 0.9 | Q56: 0.9 | R56: =0.65*J56+0.35*P56 -> 0.9 | S56: 0.9 | T56: 0.9 | U56: 0.9 | V56: 0.9 | W56: 0.9 | X56: 0.9 | Y56: 0.9 | Z56: 0.9 | AA56: 0.9 | AB56: 0.9
G57: (%) | I57: prop consumed | J57: 0.9 | K57: 0.9 | L57: 0.9 | M57: 0.75 | N57: 0.75 | O57: 0.75 | P57: 0.98 | Q57: 0.98 | R57: =0.65*J57+0.35*P57 -> 0.928 | S57: 0.9 | T57: 0.9 | U57: 0.9 | V57: 0.75 | W57: 0.75 | X57: 0.75 | Y57: 0.9 | Z57: 0.9 | AA57: 0.75 | AB57: 0.75
G58: (%) | I58: prop consumed confinement | J58: 1 | K58: 1 | L58: 1 | M58: 1 | N58: 1 | O58: 1 | P58: 1 | Q58: 1 | R58: =0.65*J58+0.35*P58 -> 1 | S58: 1 | T58: 1 | U58: 1 | V58: 1 | W58: 1 | X58: 1 | Y58: 1 | Z58: 1 | AA58: 1 | AB58: 1
G61: =G47 -> LIVESTOCK FEED - ENERGY, VOLUMES, EATEN | AF61: »
C64: «
E65: Däta | G65: LIVESTOCK FEEDS - STORAGE COSTS
G66: Cost item x Feed Type
...

Sheet CropResidue
C2: =INT($C$6)+2 -> 3
C3: =INT($C$6)+0.005 -> 1.005
B4: « | C4: =INT($C$6)+1.005 -> 2.005
C5: =INT(MAX($C$9:$C$17))+1 -> 5 | E5: 2 | F5: 2 | G5: 2.01 | H5: 1.02 | I5: 1 | J5: 1 | K5: 1 | L5: 1 | M5: 1 | N5: 1 | O5: 1 | P5: 1 | R5: 1.024 | S5: 1.024
C6: 1.02 | E6: #Inputs | F6: 2 | H6: Parameters: Version Control for the worksheet & Sheet controls
C7: =INT($C$6)+1.02 -> 2.02 | E7: Table Zoom: | F7: 1 | H7: Controls for this worksheet
C8: =INT($C$6)+2.005 -> 3.005
B9: 07Ғreeze | C9: =INT($C$6)+1.005 -> 2.005 | D9: ›
C10: =INT($C$6)+1 -> 2 | H10: Worksheet Version:
C11: =INT($C$6)+1.045 -> 2.045 | H11: Structure: | I11: 45460.954 | J11: 26Jul24: Add this version control table 1Apr19-Created the version control table
C12: =INT($C$6)+1.045 -> 2.045 | H12: Data: | I12: 45499.585 | J12: 26Jul24: Scaled SR in Ed's trials by 50% to reduce the quantity of the high quality stubble to be more similar to the average of ED & CSIRO trials 27Feb26: Add SD trial data
C13: =INT($C$6)+3.005 -> 4.005 | V13: ‹›
C14: =INT($C$6)+2.005 -> 3.005
C15: =INT($C$6)+1.005 -> 2.005 | W15: «»
C16: =INT($C$6)+0.005 -> 1.005
C17: =INT($C$6)+2 -> 3
C20: «
E21: Däta | G21: STUBBLE As Feed
G22: Crop Type
G23: 38576.729
I32: HR | J32: 1
I33: Clover propn in stubble sward | J33: 0.05
I35: Feed efficiency | K35: Efficiency if LWG then LWL | M35: 0.5
I36: Note: The reduction in efficiency is oly required if animals will be rationed to achieve the simulated LW pattern. Which is the case with high quality green feed fed to ewes at maintenance in summer, or rotating to defer pasture in winter.
G39: =G21 -> STUBBLE As Feed | W39: »
C43: «
E44: Däta | G44: Excel pre-calc inputs
C47: 0
G53: Inputs if a landuse is baled (with k axis)
H54: crop | I54: Growth scalar | J54: Regrowth scalar | K54: Propn baled | L54: Propn conserved
H55: =General!G66 -> b | I55: 0.9 | J55: 1.1 | K55: 0.7 | L55: 0.95
H56: =General!G67 -> bd | I56: 0.9 | J56: 1.1 | K56: 0.7 | L56: 0.95
H57: =General!G68 -> f | I57: 0.9 | J57: 1.1 | K57: 0.7 | L57: 0.95
H58: =General!G69 -> h | I58: 0.9 | J58: 1.1 | K58: 0.7 | L58: 0.95
H59: =General!G70 -> i | I59: 0.9 | J59: 1.1 | K59: 0.7 | L59: 0.95
H60: =General!G71 -> k | I60: 0.9 | J60: 1.1 | K60: 0.7 | L60: 0.95
H61: =General!G72 -> l | I61: 0.9 | J61: 1.1 | K61: 0.7 | L61: 0.95
H62: =General!G73 -> lf | I62: 0.9 | J62: 1.1 | K62: 0.7 | L62: 0.95
H63: =General!G74 -> ms | I63: 0.9 | J63: 1.1 | K63: 0.7 | L63: 0.95
H64: =General!G75 -> o | I64: 0.9 | J64: 1.1 | K64: 0.7 | L64: 0.95
...

Sheet ErrorChecks
C2: =INT($C$6)+2 -> 3
C3: =INT($C$6)+0.005 -> 1.005
B4: « | C4: =INT($C$6)+1.005 -> 2.005
C5: =INT(MAX($C$9:$C$20))+1 -> 5 | E5: 2 | F5: 2 | G5: 2.01 | H5: 1.15 | I5: 1 | J5: 1 | K5: 1 | L5: 1 | M5: 1 | N5: 1 | O5: 1 | P5: 1 | Q5: 1 | R5: 1 | S5: 1 | T5: 1 | U5: 1 | V5: 1 | W5: 1 | X5: 1 | Y5: 1
C6: 1.02 | E6: #Inputs | F6: 2 | H6: Version Control for the worksheet & Sheet controls
C7: =INT($C$6)+1.02 -> 2.02 | E7: Table Zoom: | F7: 1 | H7: Controls for this worksheet
C8: =INT($C$6)+2.005 -> 3.005
C9: =INT($C$6)+1.005 -> 2.005 | D9: ›
C10: =INT($C$6)+1 -> 2 | H10: Worksheet Version:
C11: =INT($C$6)+1.045 -> 2.045 | H11: Structure: | I11: 1 | J11: 1: 15Aug20-Created the version control table
C12: =INT($C$6)+1.045 -> 2.045 | H12: Data: | I12: 1 | J12: 1: 15Aug20-Blank worksheet
C13: =INT($C$6)+3.005 -> 4.005 | Z13: ‹›
C14: =INT($C$6)+3.005 -> 4.005 | D14: ›
C15: =INT($C$6)+3 -> 4 | H15: Standards: | I15: Row H: | J15: 15 | K15: Col W: | L15: 8.43 | M15: Sheet Zoom: | O15: 1
C16: =INT($C$6)+3 -> 4 | H16: User can unprotect sheet using macros | L16: TRUE
C17: =INT($C$6)+3 -> 4 | H17: User can access protected cells | L17: TRUE
C18: =INT($C$6)+3 -> 4 | H18: View gridlines on this sheet | L18: TRUE
C19: =INT($C$6)+3 -> 4 | H19: View row & column headers on this sheet | L19: TRUE
C20: =INT($C$6)+3.005 -> 4.005 | Z20: ‹›
C21: =INT($C$6)+2.005 -> 3.005
C22: =INT($C$6)+1.005 -> 2.005 | AA22: «»
C23: =INT($C$6)+0.005 -> 1.005
C24: =INT($C$6)+2 -> 3
C25: =INT($C$29)+2 -> 3
C26: =INT($C$29)+0.005 -> 1.005
B27: « | C27: =INT($C$29)+1.005 -> 2.005
C28: =INT(MAX($C$39:$C$59))+1 -> #REF!
C29: 1.02 | E29: #Inputs | H29: =COUNTIFS($B$1:$B29, "«")&" ErrorChecks: Testing consistency between the input ranges - Universal.xlsx" -> 2 ErrorChecks: Testing consistency between the input ranges - Universal.xlsx
C30: =INT($C$29)+1.02 -> 2.02 | E30: Table Zoom: | F30: 1 | H30: 1 data area
C31: =INT($C$29)+2.005 -> 3.005
C32: =INT($C$29)+2 -> 3
C33: =INT($C$29)+2 -> 3
C34: =INT($C$29)+2 -> 3
C35: =INT($C$29)+2 -> 3 | H35: Test | I35: =AND($I$39:$I$59) -> TRUE
B36: Ғilter | C36: =INT($C$29)+2.01 -> 3.01
C37: =INT(MAX($C$39:$C$59))+1 -> #REF!
B38: 07Ғreeze | C38: =INT(MAX($C$39:$C$59))+1 -> #REF!
C39: =INT($C$29)+2.005 -> 3.005 | D39: ›
C40: =INT(#REF!)+3 -> #REF! | H40: BTRT b0 | I40: =IF(COUNT($J40:$Z40)>1,STDEV($J40:$Z40)=0,"") | J40: i_cb0_len2 | K40: COUNTIFS(i_mask_b0_b1,TRUE)
C41: =INT($C$29)+2 -> 3
...

Sheet Sheep
C2: =INT($C$6)+2 -> 3
C3: =INT($C$6)+0.005 -> 1.005
B4: « | C4: =INT($C$6)+1.005 -> 2.005
C5: =INT(MAX($C$9:$C$20))+1 -> 5 | E5: 2 | F5: 2 | G5: 2.01 | H5: 1.15 | I5: 1 | J5: 1 | K5: 1 | L5: 1 | M5: 1 | N5: 1 | O5: 1 | P5: 1 | Q5: 1 | R5: 1 | S5: 1 | T5: 1 | U5: 1 | V5: 1 | W5: 1 | X5: 1 | Y5: 1 | Z5: 1 | AA5: 1 | AB5: 1 | AC5: 1 | AD5: 1 | AE5: 1 | AF5: 1 | AG5: 1
C6: 1.02 | E6: #Inputs | F6: 2 | H6: Version Control for the worksheet & Sheet controls
C7: =INT($C$6)+1.02 -> 2.02 | E7: Table Zoom: | F7: 1 | H7: Controls for this worksheet
C8: =INT($C$6)+2.005 -> 3.005
C9: =INT($C$6)+1.005 -> 2.005 | D9: ›
C10: =INT($C$6)+1 -> 2 | H10: Worksheet Version:
C11: =INT($C$6)+1.045 -> 2.045 | H11: Structure: | I11: 46051.736 | J11: 29Jan26: Added a table to report the prices for the EL analysis 30Sep25: Added EweLamb equation system for progeny survival #2, and activated it in the first p7 period (which has no effect because p7[0] is not active) 22Sep25: Add space and values for the mob size scalar for EweLambs 17Oct24: Fix error in the description of the Wool MPG percentile timeframe (it is the 10yr percentiles) 8Sep24: Change the equation groups to combine the functions that effect energy into 1 group 17Jun24: Insert sub table for the SS & SL parmaeters and include range names 14Jun24: Fix error in the STB NIB greasy formula that was subtract the cost per kg in dollars from a formula calculating cents (so cost was only 0.7c) 13Jun24: Added a web app comment to the Std FD input 10Jun24: Added tables that include the price percentiles for 5, 10 & 20yr (needs code changes to be able to run a live SA) 9May24: Expand the range for the equation range names 8May24: Added milk production equation system and tweaked commenting on the feeding standards equations. 26Nov23: Update the casual labour cost divisor in the infrastructure cost. Goes with the updated labour costs in Price! 25Nov23: Split the infrastructure cost between cash costs and labour requirement (both the fixed cost and the variable cost) 3Oct23: Add newe feeding standards equation system for foetal growth 2Oct23: Add a wool growth equation group 4May23: Add mob size scalar with an l0 axis 16Dec22: Change the wool price table to simplify the calclulations and move more into the code. 4Oct22: Add a formula that adjusts the standard saleprice to represent that the input is an average for the year. The value transferred to AFO is the price if the month scalar is 0% 2Oct22: Added indicative STB NIB greasy price to the wool table, just for information. 26Sep22: Add comment that p7 in the equation table is not p7 node periods. 20Jul22: Added range name 'prejoin_to_lamb_offset_approx' to be used in the calculation of mask_o_dams which has to be done prior to reading the other parameters that would be required to do it properly 9Jun22: Increased the range of percentile entries to include 10, 30, 50, 70 & 90 percentiles for meat. Changed the grid inputs from a price to entering the weight scalar and the score scalar. This overwrote the wether and breeder adjustments in the grids Change breeder and export prices to calculate from mutton prices. No change in price. 14Jan22: Changed the price reporting formula so that it would handle more than 3 percentile values 11Aug21: Added comments about minimum age for the $/head grids 9Aug21: Add a CFA breeder price to the meat prices reported 30Jun21: Change rangenames with m4 to p4 24Jun21: Small formatting changes of table headings 11Jun21: Delete table that included the inputs to control the sam for including LTW 25May21: Added PregTox equation system Added a 'Source' column for the price discounts table 17May21: Fixed error in reported wool prices (was missing the index of the FD deviation from the formula) 13May21: Convert the wool price report table to price of fleece wool (rather than the micron price guide) 11May21: Added a table to calcualte the wool price recieved for specified MPG & FD premium percentiles and price in each grid for meat price percentile (for reporting purposes) 5Apr21: Add Basal mortality as an equation group 30Mar21: Connect fd_prem_percentile to the STB scalar calculation. 29Mar21: Included a column for Levy as a percentage 12Feb21: Added extra inputs for the Mecardo method of calculating STB scalar (components of the clip & yield of components) Added crossbred fleece prameters for STB calcualtions Corrected wool selling costs to cost per kg clean (which is the value used in the code) 19Jan20: added LTW fleece equation group 2: 5Nov20 - Deleted pre-joining sire check & Joining (adding the sires to the ewes) Added i_len_h4 1: 10Aug20-Created the version control table
C12: =INT($C$6)+1.045 -> 2.045 | H12: Data: | I12: 46237.432 | J12: 3Aug26: Change the default PI equation system to 1 (MU equation which is a copy of CSIRO except for SAV on PI z scalar) 1Oct25: Altered peri-natal ewe mortality to eqn_system 2 & 1 (from 2,2) with addition of EL equation system to the code and dropping MU1 30Sep25: Update commenting regarding the dates for the equation systems 5Jul25: Remove premium for yearling over mutton and set monthly premiums as for mutton (differentiate again if/when the yearling market happens). 11Sep24: Update number of r_comapre vars for the Energy group after combining foetal growth, milk & wool. 8Sep24: Add extra rcompare variables to the Energy equation group 19Jun24: Change the standard percentile inputs to 50 for wool, FD prem, sale sheep and grain 17Jun24: Reverted to WA STB parameters. Added f_fibre_mu() equation system 14Jun24: Updated meat prices using AgCommodities percentiles 13Jun24: Updated the wool prices witht he half micron information from Andrew Woods 10Jun24: Added Wool price & FD percentile information from Ag Commodities & Mecardo 28May24: Add MU equation system for Heat production (eqn group 7) 9May24: Change number of Milk production variables for 'compare' to 3. Set equation system exists for NFS Milk production 7Dec23: Increase #vars for eqn_groups 1, 7, 14 & 17. To fix error now that r_compare is separate variable for each group & allow extra comparisons. 5Dec23: Estimated cost of mulesing (Ian Robertson pers comm). Updated CLik & Vetrazin costs 4Dec23: Updated husbandry prices for products that had information (very little change in price so didn't go searching for other prices) 1Dec23: Increased size of the report variable for eqn_group[7] 4Nov23: Added a NFS equation system to the LWC group (8). 1Nov23: Added a 2nd compare variable for f_foetus() 4Jun23: Reduce time required per mob for monitoring. JMY estimates. Previous assumptions had farmers spending multiple days per week monitoring. 27May23: Updated scanning costs with values from the Triplets project straw poll. 17May23: Change peri-natal dam mortality to MUChange PregTox mortality to MU equation system. 30Apr23: Update wool bale freight to $18/bale (based on latest costs) 4Oct22: Change the std meat percentile to 85. This level is similar prices to 70th percentile with formula change described above. $7/kg if sold in March. 27Sep22: Change the maximum fat score/condition score for the price tables to 10. So that when the distribution is applied when calculating the sale value that the animals above 5 are all valued at 5. 26Sep22: Changed the standard Conception system to the LMAT like equations 12Jul22: Add travel cost to the cost of scanning (after Forbes' query on travel cost). 10Jun22: Add a 12mo discount to air freight lamb and store lamb to be consistent with prime lamb (used same discount as for Prime Lamb) Updated prices in grids based on latest grids from BRM Updated percentiles to May22 (Mecardo) 23Mar22: Increase the labour required for daily monitoring to allow for 4 mob inspections per week using casual labour for the extra 3. 14Jan22: Altered Wool & Sale prices based on Mecardo percentiles 21Dec21 10Aug21: Reduced age for breeder premium price being recieved to 19mo (was 20mo). Made yearling percentile values a copy of the mutton values (because the grid prices are a copy of mutton) 17Jun21: Reduced the breeder price to make the 5.5 & 6.5 yo close to BE with the updated grid. Added the mutton price to the breeder and export wether grids to pick up the off spec animals. Scaled for the input percentile for the mutton grid relative to the export or breeders grid 15Jun21: Change scanning throughput based on values provided by Michelle Cousins (slower than previous assumptions) Reduce the yards & laneways infrastructure cost associated with animal husbandry (was 15c/hd now 5c/hd) Reduce labour requirement for mustering to 3/4 hr per mob (was 1 hr) Added a within season premium for the breeders that is the same as the mutton market up until the end of the mating period (Nov to March) Adjust the breeder sale grid (price increase of $40/hd for CS3, $45 for CS2.5 & $30 for CS4). So that CFA 5.5 & 6.5 yo are close to breakeven. 25May21: Adjusted the price discount for the prime lamb greater than 12 mo to include a discount Jul, Aug, Sep 17May21: Alter scanning cost to values provided by Michelle Cousins 6May21: Change weaner mortality to Murdoch function (=0) 5May21: Reduced shipper price to $120 max and added a gradation on the price per kg for the lighter animals 2May21: Fix error in formula for proportion of clip in greasy terms (which increased the selling costs). Improved comments for breeder grid 27Apr21: Change 'equation compare' to False 26Apr21: Reduced breeder price from $180/hd to $100/hd 16Apr21: Altered standard percentiles to Meat 70%, Wool 70% & FD Prem 50% 5Apr21: Reduce the minimum FD in the price table to 12u (because error in a fine wool team) Add Basal mortality as an equation group with MU as the standard 4Apr21: Fix error in this description (that had dam mort as group 2) 3Apr21: Change Eqn group 3 (dam mortality) to eqn system 1 (MU & LTW) 1Apr21: Fix the eqn systems used to point to MU for birth weight and lamb survival. Added comment about sat for salep grid scalars 29Mar21: Changed BW & lamb survival to use Murdoch equations. Updated livestock selling costs based on 2021 costs (Yard fees $0.79/hd, IFS $0.17/hd & Lamb levy 2%) 22Mar21: Added equation system for MU LWC 12Feb21: Altered the Wool STB parameters based on data from Mecardo newsletters 8 & 11 Feb 2021 Updated the meat prices based on the Mecardo percentiles of 11Feb21 (no changes reqd for Wool) 26: minor adjustments to the livestock sale prices update labour requirements for scanning (from Michelle). 25: Add i_salegrid_keys 1: 10Aug20-Blank worksheet
C13: =INT($C$6)+3.005 -> 4.005 | AN13: ‹›
C14: =INT($C$6)+3.005 -> 4.005 | D14: ›
C15: =INT($C$6)+3 -> 4 | H15: Standards: | I15: Row H: | J15: 15 | K15: Col W: | L15: 8.43 | M15: Sheet Zoom: | O15: 1
C16: =INT($C$6)+3 -> 4 | H16: User can unprotect sheet using macros | L16: TRUE
C17: =INT($C$6)+3 -> 4 | H17: User can access protected cells | L17: TRUE
C18: =INT($C$6)+3 -> 4 | H18: View gridlines on this sheet | L18: TRUE
C19: =INT($C$6)+3 -> 4 | H19: View row & column headers on this sheet | L19: TRUE
C20: =INT($C$6)+3.005 -> 4.005 | AN20: ‹›
C21: =INT($C$6)+2.005 -> 3.005
C22: =INT($C$6)+1.005 -> 2.005 | AO22: «»
C23: =INT($C$6)+0.005 -> 1.005
C24: =INT($C$6)+2 -> 3
C25: =INT($C$29)+2 -> 3
C26: =INT($C$29)+0.005 -> 1.005
B27: « | C27: =INT($C$29)+1.005 -> 2.005
C28: =INT(MAX($C$46:$C$55))+1 -> 5
C29: 1.02 | E29: #Inputs | H29: =COUNTIFS($B$1:$B29, "«")&" Universal: Coefficients for calculations" -> 2 Universal: Coefficients for calculations
C30: =INT($C$29)+1.02 -> 2.02 | E30: Table Zoom: | F30: 1 | H30: Proportion of dry, singles, twins & triplets from scanning % and hauteur from raw wool characteristics
C31: =INT($C$29)+2.005 -> 3.005
C32: =INT($C$29)+2 -> 3
C33: =INT($C$29)+2 -> 3
C34: =INT($C$29)+2 -> 3
C35: =INT($C$29)+2 -> 3
B36: Ғilter | C36: =INT($C$29)+2.01 -> 3.01
C37: =INT(MAX($C$46:$C$55))+1 -> 5
B38: 07Ғreeze | C38: =INT(MAX($C$46:$C$55))+1 -> 5 | J38: 0 | K38: 1 | L38: 2 | M38: 3 | N38: 4
C39: =INT($C$29)+1 -> 2 | H39: Scanning parameters: | I39: ="("&ROWS(i_scan_coeff_l0s)&","&COLUMNS(i_scan_coeff_l0s)&"): i_scan_coeff_l0s(pointers) = input" -> (4,5): i_scan_coeff_l0s(pointers) = input
C40: =INT($C$29)+1 -> 2 | H40: Source: Triplet project. Data range 100% up to 220%
C41: =INT($C$29)+3.005 -> 4.005 | AN41: ‹›
...

Sheet Emissions
C3: «
E4: Däta | G4: Global Warming Potential and Conversion Factors
G5: Scalars
G6: 2023
I10: GWP Factors | K10: Conversion Factors
H11: Gas
H13: CH4 | I13: 28 | K13: =16/12 -> 1.3333333
H15: N2O | I15: 265 | K15: =44/28 -> 1.5714286
H17: CO2 | I17: 1 | K17: =44/12 -> 3.6666667
G21: =G4 -> Global Warming Potential and Conversion Factors | AE21: »
C25: «
E26: Däta | G26: Emission Factors - National Inventory Report (NIR)
G28: 2023
H32: Stock
H33: Temperate emission factor (EFT) | L33: 0.003
H34: Faeces Emission Factor (N2O-N/N) | L34: 0.004
H35: Urine Emission Factor (N2O-N/N) | L35: 0.004
H36: Leach and Runoff Emission Factor (N2O-N/N) | L36: 0.011
H37: Urine/Faeces atmospheric deposition Emission Factor (N2O-N/N) | L37: =L51 -> 0.0018
H39: Crop Residues
H40: Residue Emission Factor (N2O-N/N) | L40: 0.00503
H41: Residue Burning Emission Factor (N2O) | L41: 0.0076
H42: Residue Burning Emission Factor (CH4) | L42: 0.0035
H44: Fuel
H45: Emission Factor CO2 (t CO2-e / kL) | L45: 2.7
H46: Emission Factor CH4 (t CO2-e / kL) | L46: 0.002123
H47: Emission Factor N2O (t CO2-e / kL) | L47: 0.01351
H49: Fert
H50: Crop - Inorganic Fert Emission Factor (N2O-N/N) | M50: 0.0029 | N50: 0.008
H51: Pasture - Inorganic Fert Emission Factor (N2O-N/N) | L51: 0.0018
H52: Crop - Inorganic Fert atmospheric deposition Emission Factor (N2O-N/N) | M52: =i_ef_fert_crop_r1 -> 0.0029 | N52: =i_ef_fert_crop_r1 -> 0.008
H53: Pasture - Inorganic Fert atmospheric deposition Emission Factor (N2O-N/N) | L53: =L51 -> 0.0018
H54: Urea Emission Factor (CO2-C/C) | L54: 0.2
H55: Limestone Emission Factor (CO2-C/C) | L55: 0.12
H56: Dolomite Emission Factor (CO2-C/C) | L56: 0.13
G59: =G26 -> Emission Factors - National Inventory Report (NIR) | AE59: »
C63: «
E64: Däta | G64: Crop & Pasture Residues & Burning
G66: 2023
W68: N content | Y68: N content
...

Sheet Parameters
G1: =COUNTIFS($B$1:$B29, "«")&" Parameters: Direct from Sheep Explorer December 2012 (downloaded - CSIRO Plant Industries" -> 2 Parameters: Direct from Sheep Explorer December 2012 (downloaded - CSIRO Plant Industries
C2: =INT($C$6)+2 -> 3
C3: =INT($C$6)+0.005 -> 1.005
B4: « | C4: =INT($C$6)+1.005 -> 2.005
C5: =INT(MAX($C$9:$C$20))+1 -> 5 | E5: 2 | F5: 2 | G5: 2.01 | H5: 1.02 | I5: 1 | J5: 1 | K5: 1 | L5: 1 | M5: 1 | N5: 1 | O5: 1 | P5: 1 | R5: 1.024 | S5: 1.024
C6: 1.02 | E6: #Inputs | F6: 2 | H6: Parameters: Version Control for the worksheet & Sheet controls
C7: =INT($C$6)+1.02 -> 2.02 | E7: Table Zoom: | F7: 1 | H7: Controls for this worksheet
C8: =INT($C$6)+2.005 -> 3.005
B9: 07Ғreeze | C9: =INT($C$6)+1.005 -> 2.005 | D9: ›
C10: =INT($C$6)+1 -> 2 | H10: Worksheet Version:
C11: =INT($C$6)+1.045 -> 2.045 | H11: Structure: | I11: 46324.338 | J11: 29Oct26: Added cg16 as a quadratic parameter for EVG, linked to code changes. Calibrated for GEPEP. Reverted change to cg11 that had been altered when cg8&9 had been lowered to aciheve 25% fat at SRW 14Oct26: Delete the inputs i_fat_propn_wean, viscera and muscle. Replaced by a calculation in the code that is linked to cg8 & cg9. 1Oct26: Fix terminology of kw slope and intercept for CSIRO equation system. Fix error in range of i_cm_c2 & _y 30Sep26: Add cm[28] to represent the increase in maintenance requirement linked to the breeding value of CFW. Add BV of CFW to the genotype parameters. 21Sep26: Add kw intercept for CSIRO function (to be used in a SAV) 19Aug26: Fixed the traits with calibration. 18Aug26: Added other calibration traits that covers the full range of EV trait coefficients 15Aug26: Added van Burgel coefficients for calculating cFAT, GR depth from CS 2Aug26: Ungrouped some rows in the parameters table that included non-zero values 1Aug26: Moved the input cells for the length and pos of the coefficients to the SheepExplorer input section (so that genotypes can be compared). Inserted ci[21 & 22] for f_pi_mu. Equivalent of ci[1 & 2]. Moved c1[21] to ci[23] so that numbering would line up. Fix number of parameters in cm (not done on 26 July 26) 27July26: Change the cn[1] coefficient to be cx[1] so that wethers can have a growth path only slightly higher than ewes while retaining 20% higher SRW. Moved cx[1] to cx[0] so cx[1] could be used in place of cn[1] 26July26: Add a coefficient for the maximum effect of the age reduction on MR for the Graham equations (Lean mass) thatt has a higher age reduction 10July26: Added parameter for fat% of an adult at the SRW (25%) 19Apr26: Changed cu2 & cu6 to position 0. Ungrouped rows of cl0 & cl1 that are used for yatf and are calculated via cb0 (progeny) 22Feb26: Split coefficient cf5 into cf5: losses prior to scanning (when conception is deemed to be quantified) and cf6: foetal losses between scanning and lambing. Only cf5 is connected in the code. 4Oct25: Swap the MU2 coefficients for EL, Mdn & Adult RR LWCj to be in slices 2 & 3 (to be consistent with cu6) 2Oct25: Added cu6 table and included cu6[8] for EL progeny survival. Note: cu3 & 4 in Pasture, cu5 in prices 23Sep25: Alter outlining levels and some text 22Sep25: Move ce_c2[2] to [0] (proportion of dry that are twice dry). Set aside ce_c2[1:6] for scan_std and other variables that might need a d axis. To be revisited when doing mobsize for EweLambs. 28Jun25: Add the new traits required for the updated EweLamb relationships from Jason's project 10Jun25: Change order of cu2 axis to suit new Maidens coefficinets (Magnificent Maidens) 29May25: Change order of the AF3 coefficients (cw[23, 24 & 25]). Add cw[26] for age related change in FD 28May25: Added 3 wool parameters to represent the lower wool production of hoggets from adults. To be calibrated by MLP data & allow calibrating YCFW separate from ACFW 17May25: Added an extra Merino genotype to use for the GEPEP analysis. Changed name of the previous GEPEP genotype to Pingelly. Moved all the '_pos' inputs to allow for the insert 19Dec24: Add ck[38] parameter so that variation in HAF with M/D can be represented in calculation of kw. Changed code for MU calc of kl & kc so these parameters are no longer used, Ungroup Parameters! cw[0] 20Sep24: Fix unrecorded change associated with converting cg[38] to weight. Required both version of proportion viscera. Added cg[39] for proportion by weight 9Sep24: Add kg for milk diet for MU functions (derived from CSIRO value) 6Sep24: Add cg[38] the proportion of protein energy gain that is viscera (to improve calculation of partitioning) 12Jul24: Fix error in formula for SD of ebg (Row 67) which was referencing CV of CS rather than LW. (no change in value) 17Jun24: Add coefficients for NEw for f_fibre_mu() (cw[0]), weight of CFW vs WB 28May24: Add coefficients to drive the Graham etal 1974 Lean mass MR equation 11May24: corrected the adding of sk[18 & 19] that didn't flow to the c2 section of the table. 9May24: Added ck[18 & 19] for the variable efficiency (BC) during gestation 3Dec23: Fix the calculation of Target muscle mass. Change description of SRW to include 'single born' 30Nov23: Reinstate genotype inputs for proportion of fat, viscera and muscle at birth (& weaning). Delete extra entry in cn that wasn't used. Altered 1_cn_len to 23 (was 8) but it isn't used 25Nov23: Change range name to i_muscle_target 23Nov23: Add cn coefficients for GR fat conversion and calculation of EBW, viscera mass & fat mass. Add cx coefficients for viscera mass. 14Nov23: Fixed outlining of the sections so no information hidden with outline 3 1Nov23: Added Pregnancy parameters for New Feeding Standards conceptus growth 30Oct23: Added DM content of wool for use in the New Feeding Stanards 4Oct23: Add coefficients ck[20-28], cm[20-22], cg[32-37] 2Oct23: Add alpha_m for each genotype. Add cg[24-31] for viscera, wool & conceptus ME & DM & alter order 18May23: Remove cu0[0] which was kg/CS because repeat of cn[5]. Add ce[23] for Peri-natal dam mortality MU1. 13May23: Add 4 extra coefficients to cu2 for SRW & DOJ for RR calculations (with square of each) 7May23: Alter variable name and description to better describe day of joining for standard scanning percentage 6May23: Add separate CV for BW and adult weight 3May23: Add Mob size parameters to BTRT - change LTW pdk scalar to mob size 30Apr23: Moved inputs for CSIRO progeny survival due to BT from cl0[11] to cl0[10]. So that slice 11 can be used for SRW adjustment (cb0[11]) 5Feb23: Added formulas to make it easy to add FOO back into the lamb survival equations. 4Feb23: Add heading for cl0[22] to alter perinatal ewe mortality by litter size (values are currently all 0) 25Sep22: Corrected the level 3 rows 24Sep22: Set outline to correct level for ce[2] 12Jul22: Open up the AgeJ^2 row for cu2 14Apr22: Add cu2[24 & 25) and cl0[24 & 25] for Ewe Lamb & LMAT repro rate calculations 6Apr22: Improve explanation of Methane parameters 11Aug21: Add a minimum age for each stock price grid (so that very young animals can't access the breeder grid) 15Jun21: Added parameters for the reduction in CFW with old age (cw17, cw18 & cw19) 26May21: Added comment about when the proportion of the flock replaced is active and moving sime inputs to other sections 24May21: Added CV of weight & CS and Std Devn of ebg for the mortality distribution calculations 17May21: Add numbers to the c2 headings 5Apr21: Add MU basal mortality equations & increase ranges for i_cd_c2 & i_cd_y 31Mar21: Delete EVG from the genotype parameters 30Mar21: Removed scaling of the cw[8] CFW efficiency because the model results indicated that SFW as defined by CSIRO actually is clean 20Mar21: Added input value for EVG (so that it could get a SA value for the MU energy function) 3: 9Sep20-Put pasture parameters in a separate pasture sheet (and linked to pasture type rather than sheep genotype) 2: 15Apr19-Added SRW of entire & castrates relative to ewes (deleted top table). Added SA for the reproduction parameters 1: 12APr19-1st draft of the table finished 2Oct23: Added Alpha_m input. Altered the inputs for cg to include viscera 14Apr: Add cu2[24 & 25] and cl0[24 & 25] for LMAT reproduction calculations 1Apr19-Created the version control table
C12: =INT($C$6)+1.045 -> 2.045 | H12: Data: | I12: 46310.416 | J12: 15Oct26: Change the partitioning parameters for the GEPEP derived genotypes. Increased fatness of young animals to reduce maintenance requirement to align with W0.75 better. SRW at 25% fat is a difficulty, because Graham 1974 has old animals much fatter. See Dropbox\Growth curve and partitioning. Help from Claude. 16Aug26: Fix error in cg9 for the GFS genotypes. Value was decreased, there was an error transcribing from the calibration spreadsheet 3Aug26: Update ci[21] for the MLP & GEPEP genotypes to reflect the increased intake parameter fitted to ci[1] 1Aug26: Revert the Fine wool & Med Merino to the old PI & EVG coefficients. Change the CFS & GFS gentoyeps to use the updated values. Differences CSIRO & GEPEP genotypes Composition (cg 8,9,11), PI (ci21) & growth constant (cx1). 28Jul26: Alter PI & EVG coefficients so that 25% fat & CS 3 align (now in c2[2 & 3] 15Jul26: Update the EVG parameters as calibrated using [Growth parameters and partitioning.xlsx] Change the Fat% at weaning based on calculation in [Growth curve & partition.xlsx]. Add reference for fat% at birth. Add calculation for proportion of viscera at birth & weaning based on proportion of lean. 14Jul26: Change GFS coefficient for calculation of energy for organs (omer). Reduced the value because it had been derived as ME but was used as NE - fixed the derivation as part of GEPEP. 29Jan26: Update the RR coefficients for 2-tooths to include the model with quadratic on LWj Update comments on source of RR for EL, 2tooth & Adults (to reflect splitting the coefficient spreadsheets) 28Jan26: Fix error in missing coefficient for CS in RR of 2 tooth maternals 14Jan26: Made the maternal proportion lactating coefficients = Merino coefficients (previously they were missing values) Tweaked the intercept for Jason's single born proportion lactating to make the adjustments for chill explicit Dec25: Updated the Ewe Lamb RR coefficients with values from RR-5k 14Oct25: Correct cl0[39] to reflect that AFO mortality is a decimal (0-1) rather than 0-100 as in the stats. 4Oct25: Change the MU2 Mdn RR coefficients to values developed in Mag Maidens (with DOJ & adjustment of LWC coefficient for absoute LW effect) 3Oct25: Fix coefficients (cu6[8] for proportion of EL lactating). Using JT updated coefficients. Correct signs in coefficients for EL dam mortality, shift coefficients to allow for LWCjoining. Correct error in cu6[23,4] 1Oct25: Add extra decimal places to Jason's lamb survival from EL coefficients 28Jun25: Enter the new coefficients for Ewe Lambs from Jason's project: Perinatal ewe (cu2[27]) & lamb survival from Ewe LW profile (cu1[19]). Alter commenting for the EweLamb coefficients referencing spreadsheets in DropBox 10Jun25: Copy Adult coefficinets to Maidens. ToDo: Maiden coefficients need updating when the values for Maidens across the c2 axis are sorted out 31May25: Undo change from yesterday because now calibrating GEPEP again. Add 'calibration' heading to the coefficients that alter the wool traits by age 30May25: Set the yearling wool age factors to 1 for the GEPEP genotypes (because they were calibrated prior to these being added) 27May25: Final update of the new GEPEP genotypes for CSIRO Feeding Standards & GEPEP Feeding Standards 20May25: Updated the new GEPEP genotypes based on the GEPEP calibration runs (CFS only as of 20May) 17May25: Alter the EVG, FD, Twin lamb survival, % drys and singles and weaning wt scalar for the GEPEP genotype for both CFS & GFS (because the production coefficients will differ) 15May25: Update the Med1 genotype. SFW 3.8kg (was 3.6kg) SFD 19u (was 20u) 19Dec24: Changed values for ck[37] & ck[38] to represent partial efficiency of wool production = 0.448. Change required to be able to represent Searle & Graham and GrazPlan kw 17Oct24: Change cp[15] for use as a scalar with sam[cp] for normal birth weight 8Sep24: Change ck[23] bgw (HP associated with gain in wool) which didn't include the -1 when converting from kw to hp. Added ck efficiency coefficients for the MU functions 11Jul24: Change GEPEP genotype calibration coefficients for start of the new calibration. 23Jun24: Update the GEPEP genotype with calibrate parameters. Not sure about the WWt parameter or the basal mortality parameter. 17Jun24: Change kw to 0.43 as per GrazPlan (using NFS parameter for kw for f_fibre_mu()). Revert NEw for GrazPlan. 17May24: Reverted to bm & bv from published paper 11May24: Changed kw for wool to allow for HAF when converting from bp 8May24: Update values for bm (cm[21]) & bv (cm[22]). Added parameters for bgc (ck[24]) & bgl (ck[25]) for the revised feeding standards 5Dec23: Improve documentation of the Blaxter & Clapperton coefficients 3Dec23: Change kw to 0.4 based on Oddy pers comm. Change Fat DM to 100% per Oddy etal 2023 (was 90% per Owen etal 1995) 30Nov23: Copy cn[22] coefficients across to the other genotypes. Was only included for fine wool merinos 5Nov23: Change variable names for b coefficients for gain/loss of energy pools 19Jul23: Alter the triplet proportion coefficients to match Jas' dataset fitted to Litter size Change the BW coefficient back to absolute BW rather than relative to SRW Adjust Merino single & twin perinatal dam mortality in MU2, so that Merino mortality is greater than Maternals - which also increases CS response Add a cap on CS in the MU2 ewe mortality coefficients 18Jul23: Fix error in the Latitude and DOJ coefficients Adjust outlining on RR to show latitude. Add a SRW coefficinet to Merino RR so that Merino SRW has equal effect to Composite LW. 17Jul23: Change SRW of MWM to 60kg & COmposite to 70kg Add a quadrtic effect to ewe mortality - may also have been errors in the coefficients that were corrected. 15Jul23: Update the Adult RR coefficients with DOJ from DPIRD scanning & use single year coefficients (remove the YIYO effect) 1Jun23: Change Merino Ewe Lambs triplets coefficient (included a high number so that there were some but not many Triplet lambs) 29May23: Recalibrate the triplet b1 coefficinet for RR to match higher % triplets from Jason. 19May23: Update the Ewe Lamb RR coefficients for the new LMAT RR calculations (that need opposite sign) 18May23: Add ewe mortality coefficients for MU2 (note: xls values are survival) Alter the SD of LWC (which impacts mortality of the MU equation). Improve commenting in CSIRO basal mortality 16May23: Update the RR coefficients to RRv5c 13May23: Fix scan_std_doj for mats. Update the RR coefficients (include DOJ & change so all components of logit equation are additive (RR used to subtract)) 13May23: Fix LS coefficients based on FOO from Gav's email 6May23: Correct the LambSurv coefficients for chill and intercept effect 2May23: Update coefficients from Triplets project. Lamb BW * Lamb survival 1May23: Added coefficients for SRW scalar (from the Triplets project) 20Feb23: Add adjustment to 2 tooth maternal lamb birthweight (based on Paganoni et al 2014) 6Feb23: Altered lamb survival coefficients as per the Triplets document (Merino triplet chill & maternal chill) 5Feb23: Improved commenting on the Preg Tox parameters 24Dec22: Improved the comments describing the lamb survival coefficients 4Oct22: Tweak survival coefficients (survival was about 10% too high for EL & ) 3Oct22: Merino EL RR intercept tweak yesterday overshot the mark, corrected. And a second tweak (back to 0) 2Oct22: Tweak the Merino ewe lamb RR intercept, Merino (different for FWM & MWM) & Maternal lamb survival intercept & Maternal EL lamb survival intercept adj 1Oct22: Remove the FOO coefficient from the Survival function because the FOO conversion was messing with the result. Need to convert the coefficient to MEI Adjust the Merino EL conception intercept. Now based on Mooj 7.5mo & NLB 15% Correct the Maternal survival cefficients that had an error associated with female chill (that was penalising the males). 30Sep22: Adjust the Survival intercept for Maternal adults & EL. Adjust RR calibration Maternal adult intercept. 29Sep22: Alter the calibration for the EL BW & Survival adjustments, the Merino & Maternal Ewe Lamb RR intercept, the Maternal RR Intercept 24Sep22: Added comments regarding halving of seasonality. Requires changing the AgeJ coefficient and the cf[0]. Removed the scalar on the BW intercept. SetLTW survival scalars to 1, to represent plot scale survival. Pdk scale is not relevant when including chill 21Sep22: Alter the AgeJ coefficient to compensate for the reduction in the seasonality coefficients. Increase the EL RR intercept to reduce overall RR to get in line with Thommo's rules of thumb Tweak the EL intercept adjustment for BW & Survival. 19Sep22: Add LMAT coefficients for Progeny survival (from BW). Adjust BW intercept to reflect variation in SRW (for Merino & Maternal) (was removed later). Altered the crg_goy & rr_doy coefficients to reduce the impact of seasonality. Add an dam age coefficient to reduce BW of yearling progeny. Add yearling progeny survival coefficient to reduce survival of yealrilng progeny 14Jul22: Reduced the SRW of the Mixed composite to 65kg from 70kg based on Ox's measurements of SRW 12Jul22: Altered the standard scanning % & survival for the medium genotype Adjust LMAT adult coefficients to incorporate DOY in the calibration & recalibrated the merino & maternal genotypes Adjust the LMAT Ewe Lamb RR coefficients to include AgeJ^2 and incorporate the effect of seasonality in the calibration. 18Apr22: Tweak the conception values so that LWCj add 15%/100g 16Apr22: Tweak maternal LMAT coefficients and add LMAT coefficients (cu2 & cl0) for merinos 13Apr22: Added cf[0] coefficient for LTW conception equation. Added scan_std_doy to correct the crg_doy calcualtion to a standard day Fix errors in LTW WWt coefficient calculations (the correction was referencing the birth weight) 4Apr22: Change Greeline and Terminal EVG intercept to 11.0 (based on LMAT phase 2) 23Jan22: Altered the wool age factor to reflect the maturing of follicles (rather than CFW by age). 25Jul21: Altered the Maternal intake to align with LMAT trial (potential intake & impact of fatness) 2Jul21: Change LTW paddocl level scalars back to 8.5 & 2, based on the similar impact on relative survival (& consistency with before) 1Jul21: Adjust the standard scanning % and lamb survival of maternal breeds Reviewed the Wwt by BTRT using LTW & LMAT (Maternal coefficients JY v7.xlsx) 24May21: Tweak base mortality coefficients to align with including the distribution on cs and ebg Added estimates of CV & SD for the mortality calcuations 17May21: Add coefficients for proportion of drys that are twice dry (_c2). 6May21: Increased base mortality to 3% and adjusted the factors for weaners and mortality due to ebg (from 20% of dNWmax to 50% before mortality increases). Tweaked RC & ebg scalars 3May21: Fix units of cm[16] Alter the proportion of flock replaced input to have all adult matings (because now summing the constraint across the k3 axis for replacements) 29Apr21: Added extra commetns about wool growth and yield. 17Apr21: Change intial LW & CFW to be a proportion of SRW & SFW (to handle altering genotypes with sa) 14Apr21: Update calibration for GEPEP Merino. 13Apr21: Change SRW of GEPEP genotype to 58.8kg (the average) 12Apr21: Increase Breeder sale age so that sold at 5.5 yo classifies as a breeder. 8Apr21: Adjusted the base mortality assumptions 7Apr21: Alter fat & protein energy density (to align with Hutton) 5Apr21: Revert basal mortality parameters to CSIRO value. Add updated parameters for MU basal mortality calculations. Increase cd_len to 27 3Apr21: Adjust Litter size parameters for Custom by adjusting both 5% & 95% Alter the basal mortality parameters to start increasing mortality if CS less than 2.5. Alter the mortality rate below the threshold 2Apr21: Update the custom animal based on the latest report 1Apr21: Change the Custom animal to reflect GEPEP average 31Mar21: Alter Med1 genotype to reflect the average GEPEP ewe production. Change std ewe age structure to 4% mortality 30Mar21: Altered wool yield to 70% based on TechPaper 2012 24Jan: Add progeny survival heading on CE[8] Added LTW prog survival paddock scale scalars Added LMAT BW & WWT coefficients (email 22May19) Estimated impact of BT3 on merino BW (based on LMAT) 18Jan: Removed intercept from LTW progeny coefficients 26: Altered Wool genotype for the terminals to 0.5 & adjusted the husbandry cut-offs for crutching & mulesing 25: Altered names in phenotype set 24: 30Nov20-Changed the dam effects on CFW & FD. Source for the original info was not attributed 1: 2Apr19-Added blank Standard Single Table
C13: =INT($C$6)+3.005 -> 4.005 | AK13: ‹›
C14: =INT($C$6)+3.005 -> 4.005 | D14: ›
C15: =INT($C$6)+3 -> 4 | H15: Standards: | I15: Row H: | J15: Row H: | K15: 15 | L15: Col W: | M15: 8.43 | N15: Sheet Zoom: | P15: 1
C16: =INT($C$6)+3 -> 4 | H16: User can unprotect sheet using macros | M16: TRUE
C17: =INT($C$6)+3 -> 4 | H17: User can access protected cells | M17: TRUE
C18: =INT($C$6)+3 -> 4 | H18: View gridlines on this sheet | M18: TRUE
C19: =INT($C$6)+3 -> 4 | H19: View row & column headers on this sheet | M19: TRUE
C20: =INT($C$6)+3.005 -> 4.005 | AK20: ‹›
C21: =INT($C$6)+2.005 -> 3.005
C22: =INT($C$6)+1.005 -> 2.005 | AL22: «»
C23: =INT($C$6)+0.005 -> 1.005
C24: =INT($C$6)+2 -> 3
C25: =INT($C$29)+2 -> 3
C26: =INT($C$29)+0.005 -> 1.005
B27: « | C27: =INT($C$29)+1.005 -> 2.005
C28: =INT(MAX($C$39:$C$2116))+1 -> 5
C29: 1.02 | E29: #Inputs | H29: =COUNTIFS($B$1:$B29, "«")&" Parameters for the stock generator" -> 2 Parameters for the stock generator
C30: =INT($C$29)+1.02 -> 2.02 | E30: Table Zoom: | F30: 1 | H30: From Sheep Explorer & Cattle Explorer December 2012 (downloaded Apr19) - CSIRO Plant Industries
C31: =INT($C$29)+2.005 -> 3.005
C32: =INT($C$29)+2 -> 3 | U32: 0 | V32: 1 | W32: 2 | X32: 3 | Y32: 4 | Z32: 5 | AA32: 6 | AB32: 7 | AC32: 8 | AD32: 9 | AE32: 10
C33: =INT($C$29)+2 -> 3 | H33: n i r k m rd a p l w c g h f d e x b0 lo l1 u0 u1 u2 | K33: Standard Values (c1 axis) | U33: Genotype Inputs (c2 axis) | AI33: Phenotypic
C34: =INT($C$29)+2 -> 3 | K34: Sheep Explorer | M34: Cattle Explorer | U34: Original CSIRO Mer | W34: MLP & GEPEP derived Merino | AB34: Composite | AC34: Maternal | AD34: Terminal | AE34: Shedders | AI34: Merit (y axis)
C35: =INT($C$29)+2 -> 3 | F35: CSIRO name | H35: Parameter description | I35: Units | K35: Wool | L35: Meat | M35: Br. Beef | N35: B. indicus | O35: Lean beef | P35: Dairy | R35: Sheep source | S35: Cattle source | U35: Fine wool | V35: Med1 | W35: SFM | X35: Bal - CFS | Y35: Bal - GFS | Z35: Meat type | AA35: Wool type | AB35: Mixed | AC35: Border | AD35: Suffolk | AE35: Dorper | AG35: Source | AI35: (sam)
B36: Ғilter | C36: =INT($C$29)+2.01 -> 3.01 | U36: 0 | V36: 1 | W36: 2 | X36: 3 | Y36: 4 | Z36: 5 | AA36: 6 | AB36: 7 | AC36: 8 | AD36: 9 | AE36: 10 | AI36: yStd | AJ36: yImp
C37: =INT(MAX($C$39:$C$2116))+1 -> 5
B38: 07Ғreeze | C38: =INT(MAX($C$39:$C$2116))+1 -> 5
C39: =INT($C$29)+2.005 -> 3.005 | D39: ›
C40: =INT($C$29)+2 -> 3 | AH40: Mask | AI40: TRUE | AJ40: FALSE
...

Sheet PastParameters
C2: =INT($C$6)+2 -> 3
C3: =INT($C$6)+0.005 -> 1.005
B4: « | C4: =INT($C$6)+1.005 -> 2.005
C5: =INT(MAX($C$9:$C$20))+1 -> 5 | E5: 2 | F5: 2 | G5: 2.01 | H5: 1.15 | I5: 1 | J5: 1 | K5: 1 | L5: 1 | M5: 1 | N5: 1 | O5: 1 | P5: 1 | Q5: 1 | R5: 1 | S5: 1 | T5: 1 | U5: 1 | V5: 1 | W5: 1 | X5: 1 | Y5: 1
C6: 1.02 | E6: #Inputs | F6: 2 | H6: Version Control for the worksheet & Sheet controls
C7: =INT($C$6)+1.02 -> 2.02 | E7: Table Zoom: | F7: 1 | H7: Controls for this worksheet
C8: =INT($C$6)+2.005 -> 3.005
C9: =INT($C$6)+1.005 -> 2.005 | D9: ›
C10: =INT($C$6)+1 -> 2 | H10: Worksheet Version:
C11: =INT($C$6)+1.045 -> 2.045 | H11: Structure: | I11: 44653.716 | J11: 2Apr22: Add i_min_grazing_limit input to be used in the RI calculation. Set value to 400 (Neville Hermann pers. comm. March 2022) 26May21: Added a second custom value for cu3 & cu4 for use with SWVic (100kg/ha to the ground) 27Apr21: Added custom pasture type for FOO conversion 2: 9Sep20-Moved the LTW pasture parameters into the sheet 1: 1Apr19-Created the version control table
C12: =INT($C$6)+1.045 -> 2.045 | H12: Data: | I12: 44664.38 | J12: 13Apr22: Improved commenting 12Apr22: Change Grazing Limit to 200kg/ha. Add a milk yield scalar of 25% for Composites to align with the increase in potential intake (from LMAT) 2Apr22: Fixed error in the exp() coefficients for the height conversion for pasture. Were 0 should have been -100 Rename Option 0 to GrazPlan rather than hand shears (because GrazPlan now appears to be above ground biomass) 1Jun21: Fix an error in the Custom parameters1 for pasture height 29Apr21: Fix error in the Custom height parameters 27Apr21:Set custom pasture parameters to old MIDAS 1: 1Apr19-Blank worksheet
C13: =INT($C$6)+3.005 -> 4.005 | Z13: ‹›
C14: =INT($C$6)+3.005 -> 4.005 | D14: ›
C15: =INT($C$6)+3 -> 4 | H15: Standards: | I15: Row H: | J15: 15 | K15: Col W: | L15: 8.43 | M15: Sheet Zoom: | O15: 1
C16: =INT($C$6)+3 -> 4 | H16: User can unprotect sheet using macros | L16: TRUE
C17: =INT($C$6)+3 -> 4 | H17: User can access protected cells | L17: TRUE
C18: =INT($C$6)+3 -> 4 | H18: View gridlines on this sheet | L18: TRUE
C19: =INT($C$6)+3 -> 4 | H19: View row & column headers on this sheet | L19: TRUE
C20: =INT($C$6)+3.005 -> 4.005 | Z20: ‹›
C21: =INT($C$6)+2.005 -> 3.005
C22: =INT($C$6)+1.005 -> 2.005 | AA22: «»
C23: =INT($C$6)+0.005 -> 1.005
C24: =INT($C$6)+2 -> 3
C25: =INT($C$29)+2 -> 3
C26: =INT($C$29)+0.005 -> 1.005
B27: « | C27: =INT($C$29)+1.005 -> 2.005
C28: =INT(MAX($C$46:$C$140))+1 -> 5
C29: 1.02 | E29: #Inputs | H29: =COUNTIFS($B$1:$B29, "«")&" PastParameters: Standard double table" -> 2 PastParameters: Standard double table
C30: =INT($C$29)+1.02 -> 2.02 | E30: Table Zoom: | F30: 1
C31: =INT($C$29)+2.005 -> 3.005
C32: =INT($C$29)+2 -> 3
C33: =INT($C$29)+2 -> 3
C34: =INT($C$29)+2 -> 3 | K34: Pasture type (align with the Pasture module type if possible)
C35: =INT($C$29)+2 -> 3 | I35: Units | K35: Generic | R35: Sources | S35: Test the WA FOO & height scalars
B36: Ғilter | C36: =INT($C$29)+2.01 -> 3.01
C37: =INT(MAX($C$46:$C$140))+1 -> 5
B38: 07Ғreeze | C38: =INT(MAX($C$46:$C$140))+1 -> 5
C39: =INT($C$29)+2.005 -> 3.005 | D39: ›
C40: =INT($C$29)+2 -> 3 | H40: GrazPlan feedbase parameters
C41: =INT($C$29)+2 -> 3 | H41: Standard height density (height per unit of FOO) | I41: mm / (kg/ha) | K41: =30/1000 -> 0.03 | R41: 0.03 TechPaper 2012, 0.015 to represent dense clover pasture
...

Sheet Mach General
A2: Variable dep
A3: variable_dep_hr_harv | B3: 7e-05 | C3: %/ rotor hr
A4: variable_dep_hr_seeding | B4: 0.00013 | C4: %/ tractor hr
A5: variable_dep_hr_spraying | B5: 0.00019 | C5: %/ sprayer hr
A6: variable_dep_hr_spreading | B6: 0.00019 | C6: %/ tractor hr
A8: Hay
A9: approx_hay_yield | B9: 7
A12: Contract Harvesting
A14: contract_harvest_rate
A15: =General!G66 -> b | B15: 20 | C15: t/ machine hr
A16: =General!G67 -> bd | B16: 20 | C16: t/ machine hr
A17: =General!G68 -> f | B17: 7 | C17: t/ machine hr
A18: =General!G69 -> h | B18: 20 | C18: t/ machine hr
A19: =General!G70 -> i | B19: 7 | C19: t/ machine hr
A20: =General!G71 -> k | B20: 7 | C20: t/ machine hr
A21: =General!G72 -> l | B21: 7 | C21: t/ machine hr
A22: =General!G73 -> lf | B22: 7 | C22: t/ machine hr
A23: =General!G74 -> ms | B23: =0.65*B15+0.35*B21 -> 15.45 | C23: t/ machine hr
A24: =General!G75 -> o | B24: 20 | C24: t/ machine hr
A25: =General!G76 -> od | B25: 20 | C25: t/ machine hr
A26: =General!G77 -> of | B26: 20 | C26: t/ machine hr
A27: =General!G78 -> r | B27: 7 | C27: t/ machine hr
A28: =General!G79 -> rd | B28: 7 | C28: t/ machine hr
